Workbook

Sheet Сводка
A1: The Aldera · финансовая модель · сводка
A2: 518 GROUP LLC. 4 продукта Vox Nutrition, каналы TikTok Shop, Shopify, Amazon. Старт продаж 20.11.2026. Вложение двумя траншами. Платная реклама только Spark Ads на выстрелившие ролики, с февраля 2027.
A3: Активный сценарий (1 конс., 2 база, 3 опт.): | C3: =Допущения!B3 -> 2
A5: Показатель | B5: Год 1 | C5: Год 2 | D5: Год 3
A6: Выручка | B6: ='Итоги по годам'!B16 -> 3677785.5 | C6: ='Итоги по годам'!C16 -> 12077196 | D6: ='Итоги по годам'!D16 -> 21146706
A7: Маржинальная прибыль | B7: ='Итоги по годам'!B27 -> 1388534.1 | C7: ='Итоги по годам'!C27 -> 5197233.3 | D7: ='Итоги по годам'!D27 -> 9558712.3
A8: Маржинальность | B8: ='Итоги по годам'!B41 -> 0.37754625 | C8: ='Итоги по годам'!C41 -> 0.43033443 | D8: ='Итоги по годам'!D41 -> 0.45201898
A9: Постоянные расходы | B9: ='Итоги по годам'!B34 -> 200450.8 | C9: ='Итоги по годам'!C34 -> 596585.6 | D9: ='Итоги по годам'!D34 -> 829532.35
A10: EBITDA | B10: ='Итоги по годам'!B35 -> 1188083.3 | C10: ='Итоги по годам'!C35 -> 4600647.7 | D10: ='Итоги по годам'!D35 -> 8729180
A11: Рентабельность по EBITDA | B11: ='Итоги по годам'!B42 -> 0.32304313 | C11: ='Итоги по годам'!C42 -> 0.38093674 | D11: ='Итоги по годам'!D42 -> 0.41279148
A12: Чистая прибыль после налога (оценка) | B12: ='Итоги по годам'!B37 -> 891062.49 | C12: ='Итоги по годам'!C37 -> 3450485.8 | D12: ='Итоги по годам'!D37 -> 6546885
A13: Заказов всего | B13: ='Итоги по годам'!B9 -> 74271.075 | C13: ='Итоги по годам'!C9 -> 237924.82 | D13: ='Итоги по годам'!D9 -> 405293.53
A14: Подписчиков на конец года | B14: ='Итоги по годам'!B43 -> 3893.9825 | C14: ='Итоги по годам'!C43 -> 10187.6 | D14: ='Итоги по годам'!D43 -> 17004.955
A15: Криейторов на конец года | B15: ='Итоги по годам'!B44 -> 150 | C15: ='Итоги по годам'!C44 -> 294 | D15: ='Итоги по годам'!D44 -> 400
A16: Деньги на счёте на конец года | B16: ='Итоги по годам'!B45 -> 624408.93 | C16: ='Итоги по годам'!C45 -> 3804061.4 | D16: ='Итоги по годам'!D45 -> 10138854
A18: Минимум денег на счёте | B18: ='Итоги по годам'!E46 -> -8323.2387
A19: Месяц выхода на темп $1 млн EBITDA в год (1 = ноябрь 2026) | B19: ='Итоги по годам'!E47 -> 7
A21: Главные выводы (базовый сценарий, снимок 03.10.2026)
A22: • Вложения окупаются EBITDA на 2-м месяце (декабрь 2026), темп $1 млн EBITDA в год на 7-м месяце (май 2027).
A23: • Узкое место декабрь 2026: при запасе товара 1,3 месяца денег не хватает на $8 323. Решение: второй транш $21 000 вместо $5 000 (покрывает 90% исходов Монте-Карло) или запас 1,0 месяца в декабре.
A24: • Монте-Карло, 5 000 прогонов: EBITDA года 1 от $547 тыс. (P10) до $1 391 тыс. (P90), медиана $875 тыс.
A25: • Вероятность EBITDA года 2 не меньше $1 млн: больше 99%. Вероятность, что при транше $5 000 денег не хватит: 68%, нехватка до $15 508 (P90).
A26: • Главные рычаги прибыли: конверсия просмотра в заказ, просмотры на ролик, скорость набора криейторов, переход в подписку.
A27: • Без Amazon EBITDA года 1 остаётся в плюсе уже при конверсии 0,0041%; $1 млн EBITDA во 2-м году без Amazon при конверсии от 0,016%.

Sheet Итоги по годам
A1: The Aldera · итоги по годам модели
A2: Год 1: ноябрь 2026 - октябрь 2027. Год 2: ноябрь 2027 - октябрь 2028. Год 3: ноябрь 2028 - октябрь 2029. Сценарий на листе «Допущения», ячейка B3.
A4: Показатель | B4: Год 1 | C4: Год 2 | D4: Год 3 | E4: Итого 3 года
A5: Заказы TikTok | B5: =SUMIF(Модель!$D$5:$AM$5,1,Модель!$D$12:$AM$12) -> 34358 | C5: =SUMIF(Модель!$D$5:$AM$5,2,Модель!$D$12:$AM$12) -> 87516 | D5: =SUMIF(Модель!$D$5:$AM$5,3,Модель!$D$12:$AM$12) -> 140730.72 | E5: =SUM(B5:D5) -> 262604.72
A6: Заказы Shopify прямые | B6: =SUMIF(Модель!$D$5:$AM$5,1,Модель!$D$13:$AM$13) -> 3435.8 | C6: =SUMIF(Модель!$D$5:$AM$5,2,Модель!$D$13:$AM$13) -> 8751.6 | D6: =SUMIF(Модель!$D$5:$AM$5,3,Модель!$D$13:$AM$13) -> 14073.072 | E6: =SUM(B6:D6) -> 26260.472
A7: Заказы подписки | B7: =SUMIF(Модель!$D$5:$AM$5,1,Модель!$D$16:$AM$16) -> 17750.875 | C7: =SUMIF(Модель!$D$5:$AM$5,2,Модель!$D$16:$AM$16) -> 81465.221 | D7: =SUMIF(Модель!$D$5:$AM$5,3,Модель!$D$16:$AM$16) -> 164032.14 | E7: =SUM(B7:D7) -> 263248.24
A8: Заказы Amazon | B8: =SUMIF(Модель!$D$5:$AM$5,1,Модель!$D$18:$AM$18) -> 18726.4 | C8: =SUMIF(Модель!$D$5:$AM$5,2,Модель!$D$18:$AM$18) -> 60192 | D8: =SUMIF(Модель!$D$5:$AM$5,3,Модель!$D$18:$AM$18) -> 86457.6 | E8: =SUM(B8:D8) -> 165376
A9: Всего заказов | B9: =SUMIF(Модель!$D$5:$AM$5,1,Модель!$D$19:$AM$19) -> 74271.075 | C9: =SUMIF(Модель!$D$5:$AM$5,2,Модель!$D$19:$AM$19) -> 237924.82 | D9: =SUMIF(Модель!$D$5:$AM$5,3,Модель!$D$19:$AM$19) -> 405293.53 | E9: =SUM(B9:D9) -> 717489.43
A10: Банок продано | B10: =SUMIF(Модель!$D$5:$AM$5,1,Модель!$D$25:$AM$25) -> 118692.18 | C10: =SUMIF(Модель!$D$5:$AM$5,2,Модель!$D$25:$AM$25) -> 395480.28 | D10: =SUMIF(Модель!$D$5:$AM$5,3,Модель!$D$25:$AM$25) -> 699115.18 | E10: =SUM(B10:D10) -> 1213287.6
A12: Выручка TikTok Shop | B12: =SUMIF(Модель!$D$5:$AM$5,1,Модель!$D$32:$AM$32) -> 1745386.4 | C12: =SUMIF(Модель!$D$5:$AM$5,2,Модель!$D$32:$AM$32) -> 4445812.8 | D12: =SUMIF(Модель!$D$5:$AM$5,3,Модель!$D$32:$AM$32) -> 7149120.6 | E12: =SUM(B12:D12) -> 13340320
A13: Выручка Shopify: первые | B13: =SUMIF(Модель!$D$5:$AM$5,1,Модель!$D$33:$AM$33) -> 174538.64 | C13: =SUMIF(Модель!$D$5:$AM$5,2,Модель!$D$33:$AM$33) -> 444581.28 | D13: =SUMIF(Модель!$D$5:$AM$5,3,Модель!$D$33:$AM$33) -> 714912.06 | E13: =SUM(B13:D13) -> 1334032
A14: Выручка Shopify: подписка | B14: =SUMIF(Модель!$D$5:$AM$5,1,Модель!$D$34:$AM$34) -> 1117417.5 | C14: =SUMIF(Модель!$D$5:$AM$5,2,Модель!$D$34:$AM$34) -> 5128235.7 | D14: =SUMIF(Модель!$D$5:$AM$5,3,Модель!$D$34:$AM$34) -> 10325823 | E14: =SUM(B14:D14) -> 16571476
A15: Выручка Amazon | B15: =SUMIF(Модель!$D$5:$AM$5,1,Модель!$D$35:$AM$35) -> 640442.88 | C15: =SUMIF(Модель!$D$5:$AM$5,2,Модель!$D$35:$AM$35) -> 2058566.4 | D15: =SUMIF(Модель!$D$5:$AM$5,3,Модель!$D$35:$AM$35) -> 2956849.9 | E15: =SUM(B15:D15) -> 5655859.2
A16: Выручка всего | B16: =SUMIF(Модель!$D$5:$AM$5,1,Модель!$D$36:$AM$36) -> 3677785.5 | C16: =SUMIF(Модель!$D$5:$AM$5,2,Модель!$D$36:$AM$36) -> 12077196 | D16: =SUMIF(Модель!$D$5:$AM$5,3,Модель!$D$36:$AM$36) -> 21146706 | E16: =SUM(B16:D16) -> 36901687
A18: Товар (Vox) | B18: =SUMIF(Модель!$D$5:$AM$5,1,Модель!$D$38:$AM$38) -> 766640.74 | C18: =SUMIF(Модель!$D$5:$AM$5,2,Модель!$D$38:$AM$38) -> 2373776.3 | D18: =SUMIF(Модель!$D$5:$AM$5,3,Модель!$D$38:$AM$38) -> 4124801.4 | E18: =SUM(B18:D18) -> 7265218.4
A19: Комиссия TikTok Shop | B19: =SUMIF(Модель!$D$5:$AM$5,1,Модель!$D$39:$AM$39) -> 139630.91 | C19: =SUMIF(Модель!$D$5:$AM$5,2,Модель!$D$39:$AM$39) -> 355665.02 | D19: =SUMIF(Модель!$D$5:$AM$5,3,Модель!$D$39:$AM$39) -> 571929.65 | E19: =SUM(B19:D19) -> 1067225.6
A20: Комиссия криейторов | B20: =SUMIF(Модель!$D$5:$AM$5,1,Модель!$D$40:$AM$40) -> 523615.92 | C20: =SUMIF(Модель!$D$5:$AM$5,2,Модель!$D$40:$AM$40) -> 1333743.8 | D20: =SUMIF(Модель!$D$5:$AM$5,3,Модель!$D$40:$AM$40) -> 2144736.2 | E20: =SUM(B20:D20) -> 4002095.9
A21: Эквайринг Shopify | B21: =SUMIF(Модель!$D$5:$AM$5,1,Модель!$D$41:$AM$41) -> 43822.732 | C21: =SUMIF(Модель!$D$5:$AM$5,2,Модель!$D$41:$AM$41) -> 188676.74 | D21: =SUMIF(Модель!$D$5:$AM$5,3,Модель!$D$41:$AM$41) -> 373612.89 | E21: =SUM(B21:D21) -> 606112.36
A22: Amazon: комиссия и FBA | B22: =SUMIF(Модель!$D$5:$AM$5,1,Модель!$D$42:$AM$42) -> 210110.21 | C22: =SUMIF(Модель!$D$5:$AM$5,2,Модель!$D$42:$AM$42) -> 675354.24 | D22: =SUMIF(Модель!$D$5:$AM$5,3,Модель!$D$42:$AM$42) -> 970054.27 | E22: =SUM(B22:D22) -> 1855518.7
A23: Amazon: реклама PPC | B23: =SUMIF(Модель!$D$5:$AM$5,1,Модель!$D$43:$AM$43) -> 96066.432 | C23: =SUMIF(Модель!$D$5:$AM$5,2,Модель!$D$43:$AM$43) -> 308784.96 | D23: =SUMIF(Модель!$D$5:$AM$5,3,Модель!$D$43:$AM$43) -> 443527.49 | E23: =SUM(B23:D23) -> 848378.88
A24: Доставка покупателю | B24: =SUMIF(Модель!$D$5:$AM$5,1,Модель!$D$44:$AM$44) -> 292302.01 | C24: =SUMIF(Модель!$D$5:$AM$5,2,Модель!$D$44:$AM$44) -> 954798.96 | D24: =SUMIF(Модель!$D$5:$AM$5,3,Модель!$D$44:$AM$44) -> 1726953.4 | E24: =SUM(B24:D24) -> 2974054.4
A25: Склад-отправщик | B25: =SUMIF(Модель!$D$5:$AM$5,1,Модель!$D$45:$AM$45) -> 138861.69 | C25: =SUMIF(Модель!$D$5:$AM$5,2,Модель!$D$45:$AM$45) -> 444332.05 | D25: =SUMIF(Модель!$D$5:$AM$5,3,Модель!$D$45:$AM$45) -> 797089.83 | E25: =SUM(B25:D25) -> 1380283.6
A26: Возвраты | B26: =SUMIF(Модель!$D$5:$AM$5,1,Модель!$D$46:$AM$46) -> 78200.716 | C26: =SUMIF(Модель!$D$5:$AM$5,2,Модель!$D$46:$AM$46) -> 244830.72 | D26: =SUMIF(Модель!$D$5:$AM$5,3,Модель!$D$46:$AM$46) -> 435288.32 | E26: =SUM(B26:D26) -> 758319.76
A27: Маржинальная прибыль | B27: =SUMIF(Модель!$D$5:$AM$5,1,Модель!$D$48:$AM$48) -> 1388534.1 | C27: =SUMIF(Модель!$D$5:$AM$5,2,Модель!$D$48:$AM$48) -> 5197233.3 | D27: =SUMIF(Модель!$D$5:$AM$5,3,Модель!$D$48:$AM$48) -> 9558712.3 | E27: =SUM(B27:D27) -> 16144480
A29: Сервисы и ПО | B29: =SUMIF(Модель!$D$5:$AM$5,1,Модель!$D$51:$AM$51) -> 6000 | C29: =SUMIF(Модель!$D$5:$AM$5,2,Модель!$D$51:$AM$51) -> 12000 | D29: =SUMIF(Модель!$D$5:$AM$5,3,Модель!$D$51:$AM$51) -> 18000 | E29: =SUM(B29:D29) -> 36000
A30: Страховка | B30: =SUMIF(Модель!$D$5:$AM$5,1,Модель!$D$52:$AM$52) -> 2150 | C30: =SUMIF(Модель!$D$5:$AM$5,2,Модель!$D$52:$AM$52) -> 6000 | D30: =SUMIF(Модель!$D$5:$AM$5,3,Модель!$D$52:$AM$52) -> 6000 | E30: =SUM(B30:D30) -> 14150
A31: Бухгалтерия и юристы | B31: =SUMIF(Модель!$D$5:$AM$5,1,Модель!$D$53:$AM$53) -> 3600 | C31: =SUMIF(Модель!$D$5:$AM$5,2,Модель!$D$53:$AM$53) -> 3600 | D31: =SUMIF(Модель!$D$5:$AM$5,3,Модель!$D$53:$AM$53) -> 3600 | E31: =SUM(B31:D31) -> 10800
A32: Команда | B32: =SUMIF(Модель!$D$5:$AM$5,1,Модель!$D$54:$AM$54) -> 68000 | C32: =SUMIF(Модель!$D$5:$AM$5,2,Модель!$D$54:$AM$54) -> 233000 | D32: =SUMIF(Модель!$D$5:$AM$5,3,Модель!$D$54:$AM$54) -> 252000 | E32: =SUM(B32:D32) -> 553000
A33: Реклама: Spark Ads и прочая | B33: =SUMIF(Модель!$D$5:$AM$5,1,Модель!$D$55:$AM$55) -> 120700.8 | C33: =SUMIF(Модель!$D$5:$AM$5,2,Модель!$D$55:$AM$55) -> 341985.6 | D33: =SUMIF(Модель!$D$5:$AM$5,3,Модель!$D$55:$AM$55) -> 549932.35 | E33: =SUM(B33:D33) -> 1012618.8
A34: Постоянные расходы | B34: =SUMIF(Модель!$D$5:$AM$5,1,Модель!$D$56:$AM$56) -> 200450.8 | C34: =SUMIF(Модель!$D$5:$AM$5,2,Модель!$D$56:$AM$56) -> 596585.6 | D34: =SUMIF(Модель!$D$5:$AM$5,3,Модель!$D$56:$AM$56) -> 829532.35 | E34: =SUM(B34:D34) -> 1626568.8
A35: EBITDA (прибыль до налога) | B35: =SUMIF(Модель!$D$5:$AM$5,1,Модель!$D$57:$AM$57) -> 1188083.3 | C35: =SUMIF(Модель!$D$5:$AM$5,2,Модель!$D$57:$AM$57) -> 4600647.7 | D35: =SUMIF(Модель!$D$5:$AM$5,3,Модель!$D$57:$AM$57) -> 8729180 | E35: =SUM(B35:D35) -> 14517911
A36: Налог, оценка | B36: =SUMIF(Модель!$D$5:$AM$5,1,Модель!$D$58:$AM$58) -> 297020.83 | C36: =SUMIF(Модель!$D$5:$AM$5,2,Модель!$D$58:$AM$58) -> 1150161.9 | D36: =SUMIF(Модель!$D$5:$AM$5,3,Модель!$D$58:$AM$58) -> 2182295 | E36: =SUM(B36:D36) -> 3629477.8
A37: Чистая прибыль | B37: =SUMIF(Модель!$D$5:$AM$5,1,Модель!$D$59:$AM$59) -> 891062.49 | C37: =SUMIF(Модель!$D$5:$AM$5,2,Модель!$D$59:$AM$59) -> 3450485.8 | D37: =SUMIF(Модель!$D$5:$AM$5,3,Модель!$D$59:$AM$59) -> 6546885 | E37: =SUM(B37:D37) -> 10888433
A39: Закупка товара у Vox | B39: =SUMIF(Модель!$D$5:$AM$5,1,Модель!$D$69:$AM$69) -> 934218.5 | C39: =SUMIF(Модель!$D$5:$AM$5,2,Модель!$D$69:$AM$69) -> 2557745.5 | D39: =SUMIF(Модель!$D$5:$AM$5,3,Модель!$D$69:$AM$69) -> 4267797 | E39: =SUM(B39:D39) -> 7759761
A41: Маржинальность | B41: =IF(B16=0,0,B27/B16) -> 0.37754625 | C41: =IF(C16=0,0,C27/C16) -> 0.43033443 | D41: =IF(D16=0,0,D27/D16) -> 0.45201898 | E41: =IF(E16=0,0,E27/E16) -> 0.43749977
A42: Рентабельность по EBITDA | B42: =IF(B16=0,0,B35/B16) -> 0.32304313 | C42: =IF(C16=0,0,C35/C16) -> 0.38093674 | D42: =IF(D16=0,0,D35/D16) -> 0.41279148 | E42: =IF(E16=0,0,E35/E16) -> 0.39342133
A43: Подписчиков на конец года | B43: =INDEX(Модель!$D$15:$AM$15,12) -> 3893.9825 | C43: =INDEX(Модель!$D$15:$AM$15,24) -> 10187.6 | D43: =INDEX(Модель!$D$15:$AM$15,36) -> 17004.955
A44: Криейторов на конец года | B44: =INDEX(Модель!$D$9:$AM$9,12) -> 150 | C44: =INDEX(Модель!$D$9:$AM$9,24) -> 294 | D44: =INDEX(Модель!$D$9:$AM$9,36) -> 400
A45: Деньги на счёте на конец года | B45: =INDEX(Модель!$D$73:$AM$73,12) -> 624408.93 | C45: =INDEX(Модель!$D$73:$AM$73,24) -> 3804061.4 | D45: =INDEX(Модель!$D$73:$AM$73,36) -> 10138854
A46: Минимум денег на счёте за 3 года | E46: =MIN(Модель!$C$73:$AM$73) -> -8323.2387
...

Sheet KPI по кварталам
A1: KPI по кварталам: цели для ежемесячного контроля
A2: Квартал 1 = ноябрь 2026 - январь 2027. Живые формулы из листа «Модель».
A4: Показатель | B4: Q1 ноя26-янв27 | C4: Q2 фев-апр27 | D4: Q3 май-июл27 | E4: Q4 авг-окт27 | F4: Q5 ноя27-янв28 | G4: Q6 фев-апр28 | H4: Q7 май-июл28 | I4: Q8 авг-окт28 | J4: Q9 | K4: Q10 | L4: Q11 | M4: Q12
A5: Криейторов на конец квартала | B5: =Модель!F9 -> 60 | C5: =Модель!I9 -> 90 | D5: =Модель!L9 -> 120 | E5: =Модель!O9 -> 150 | F5: =Модель!R9 -> 186 | G5: =Модель!U9 -> 222 | H5: =Модель!X9 -> 258 | I5: =Модель!AA9 -> 294 | J5: =Модель!AD9 -> 330 | K5: =Модель!AG9 -> 366 | L5: =Модель!AJ9 -> 400 | M5: =Модель!AM9 -> 400
A6: Роликов вышло | B6: =SUM(Модель!D10:F10) -> 1026.6667 | C6: =SUM(Модель!G10:I10) -> 1920 | D6: =SUM(Модель!J10:L10) -> 2640 | E6: =SUM(Модель!M10:O10) -> 3360 | F6: =SUM(Модель!P10:R10) -> 4176 | G6: =SUM(Модель!S10:U10) -> 5040 | H6: =SUM(Модель!V10:X10) -> 5904 | I6: =SUM(Модель!Y10:AA10) -> 6768 | J6: =SUM(Модель!AB10:AD10) -> 7632 | K6: =SUM(Модель!AE10:AG10) -> 8496 | L6: =SUM(Модель!AH10:AJ10) -> 9344 | M6: =SUM(Модель!AK10:AM10) -> 9600
A7: Просмотров, млн | B7: =SUM(Модель!D11:F11)/1000000 -> 5.1333333 | C7: =SUM(Модель!G11:I11)/1000000 -> 9.6 | D7: =SUM(Модель!J11:L11)/1000000 -> 13.2 | E7: =SUM(Модель!M11:O11)/1000000 -> 16.8 | F7: =SUM(Модель!P11:R11)/1000000 -> 20.88 | G7: =SUM(Модель!S11:U11)/1000000 -> 25.2 | H7: =SUM(Модель!V11:X11)/1000000 -> 29.52 | I7: =SUM(Модель!Y11:AA11)/1000000 -> 33.84 | J7: =SUM(Модель!AB11:AD11)/1000000 -> 38.16 | K7: =SUM(Модель!AE11:AG11)/1000000 -> 42.48 | L7: =SUM(Модель!AH11:AJ11)/1000000 -> 46.72 | M7: =SUM(Модель!AK11:AM11)/1000000 -> 48
A8: Заказы TikTok | B8: =SUM(Модель!D12:F12) -> 3470 | C8: =SUM(Модель!G12:I12) -> 7488 | D8: =SUM(Модель!J12:L12) -> 10296 | E8: =SUM(Модель!M12:O12) -> 13104 | F8: =SUM(Модель!P12:R12) -> 18439.2 | G8: =SUM(Модель!S12:U12) -> 19656 | H8: =SUM(Модель!V12:X12) -> 23025.6 | I8: =SUM(Модель!Y12:AA12) -> 26395.2 | J8: =SUM(Модель!AB12:AD12) -> 33714.72 | K8: =SUM(Модель!AE12:AG12) -> 33134.4 | L8: =SUM(Модель!AH12:AJ12) -> 36441.6 | M8: =SUM(Модель!AK12:AM12) -> 37440
A9: Заказы Shopify первые | B9: =SUM(Модель!D13:F13) -> 347 | C9: =SUM(Модель!G13:I13) -> 748.8 | D9: =SUM(Модель!J13:L13) -> 1029.6 | E9: =SUM(Модель!M13:O13) -> 1310.4 | F9: =SUM(Модель!P13:R13) -> 1843.92 | G9: =SUM(Модель!S13:U13) -> 1965.6 | H9: =SUM(Модель!V13:X13) -> 2302.56 | I9: =SUM(Модель!Y13:AA13) -> 2639.52 | J9: =SUM(Модель!AB13:AD13) -> 3371.472 | K9: =SUM(Модель!AE13:AG13) -> 3313.44 | L9: =SUM(Модель!AH13:AJ13) -> 3644.16 | M9: =SUM(Модель!AK13:AM13) -> 3744
A10: Заказы подписки | B10: =SUM(Модель!D16:F16) -> 386.331 | C10: =SUM(Модель!G16:I16) -> 2543.4388 | D10: =SUM(Модель!J16:L16) -> 5650.3021 | E10: =SUM(Модель!M16:O16) -> 9170.8026 | F10: =SUM(Модель!P16:R16) -> 13405.045 | G10: =SUM(Модель!S16:U16) -> 18182.771 | H10: =SUM(Модель!V16:X16) -> 22581.872 | I10: =SUM(Модель!Y16:AA16) -> 27295.533 | J10: =SUM(Модель!AB16:AD16) -> 32933.025 | K10: =SUM(Модель!AE16:AG16) -> 38926.647 | L10: =SUM(Модель!AH16:AJ16) -> 43731.024 | M10: =SUM(Модель!AK16:AM16) -> 48441.444
A11: Подписчиков на конец | B11: =Модель!F15 -> 533.9169 | C11: =Модель!I15 -> 1515.093 | D11: =Модель!L15 -> 2648.9028 | E11: =Модель!O15 -> 3893.9825 | F11: =Модель!R15 -> 5595.946 | G11: =Модель!U15 -> 7020.9089 | H11: =Модель!X15 -> 8561.9457 | I11: =Модель!AA15 -> 10187.6 | J11: =Модель!AD15 -> 12457.227 | K11: =Модель!AG15 -> 14031.738 | L11: =Модель!AJ15 -> 15671.5 | M11: =Модель!AM15 -> 17004.955
A12: Заказы Amazon | B12: =SUM(Модель!D18:F18) -> 0 | C12: =SUM(Модель!G18:I18) -> 1722.6667 | D12: =SUM(Модель!J18:L18) -> 6384 | E12: =SUM(Модель!M18:O18) -> 10619.733 | F12: =SUM(Модель!P18:R18) -> 12585.6 | G12: =SUM(Модель!S18:U18) -> 14227.2 | H12: =SUM(Модель!V18:X18) -> 15868.8 | I12: =SUM(Модель!Y18:AA18) -> 17510.4 | J12: =SUM(Модель!AB18:AD18) -> 19152 | K12: =SUM(Модель!AE18:AG18) -> 20793.6 | L12: =SUM(Модель!AH18:AJ18) -> 22435.2 | M12: =SUM(Модель!AK18:AM18) -> 24076.8
A13: Выручка | B13: =SUM(Модель!D36:F36) -> 218223.14 | C13: =SUM(Модель!G36:I36) -> 637454.11 | D13: =SUM(Модель!J36:L36) -> 1149359.8 | E13: =SUM(Модель!M36:O36) -> 1672748.4 | F13: =SUM(Модель!P36:R36) -> 2304657.6 | G13: =SUM(Модель!S36:U36) -> 2729553 | H13: =SUM(Модель!V36:X36) -> 3250912.3 | I13: =SUM(Модель!Y36:AA36) -> 3792073.3 | J13: =SUM(Модель!AB36:AD36) -> 4612110.9 | K13: =SUM(Модель!AE36:AG36) -> 5013123.8 | L13: =SUM(Модель!AH36:AJ36) -> 5556508.4 | M13: =SUM(Модель!AK36:AM36) -> 5964962.7
A14: Маржинальная прибыль | B14: =SUM(Модель!D48:F48) -> 63785.236 | C14: =SUM(Модель!G48:I48) -> 223114.41 | D14: =SUM(Модель!J48:L48) -> 434922.5 | E14: =SUM(Модель!M48:O48) -> 666711.97 | F14: =SUM(Модель!P48:R48) -> 941963.37 | G14: =SUM(Модель!S48:U48) -> 1169520.9 | H14: =SUM(Модель!V48:X48) -> 1416428.1 | I14: =SUM(Модель!Y48:AA48) -> 1669321 | J14: =SUM(Модель!AB48:AD48) -> 2025862.9 | K14: =SUM(Модель!AE48:AG48) -> 2264742.9 | L14: =SUM(Модель!AH48:AJ48) -> 2525473.5 | M14: =SUM(Модель!AK48:AM48) -> 2742633
A15: EBITDA | B15: =SUM(Модель!D57:F57) -> 60935.236 | C15: =SUM(Модель!G57:I57) -> 180003.61 | D15: =SUM(Модель!J57:L57) -> 370838.9 | E15: =SUM(Модель!M57:O57) -> 576305.57 | F15: =SUM(Модель!P57:R57) -> 816508.65 | G15: =SUM(Модель!S57:U57) -> 1028311.3 | H15: =SUM(Модель!V57:X57) -> 1258051.2 | I15: =SUM(Модель!Y57:AA57) -> 1497776.6 | J15: =SUM(Модель!AB57:AD57) -> 1824216.1 | K15: =SUM(Модель!AE57:AG57) -> 2065363.9 | L15: =SUM(Модель!AH57:AJ57) -> 2313171 | M15: =SUM(Модель!AK57:AM57) -> 2526429
A16: Закупка у Vox | B16: =SUM(Модель!D69:F69) -> 75472.5 | C16: =SUM(Модель!G69:I69) -> 182142.5 | D16: =SUM(Модель!J69:L69) -> 286350.5 | E16: =SUM(Модель!M69:O69) -> 390253 | F16: =SUM(Модель!P69:R69) -> 493635.5 | G16: =SUM(Модель!S69:U69) -> 577216 | H16: =SUM(Модель!V69:X69) -> 680785 | I16: =SUM(Модель!Y69:AA69) -> 806109 | J16: =SUM(Модель!AB69:AD69) -> 936990 | K16: =SUM(Модель!AE69:AG69) -> 1025493 | L16: =SUM(Модель!AH69:AJ69) -> 1124077 | M16: =SUM(Модель!AK69:AM69) -> 1181237
A17: Деньги на конец квартала | B17: =Модель!F73 -> -246.78277 | C17: =Модель!I73 -> 60870.341 | D17: =Модель!L73 -> 266721.67 | E17: =Модель!O73 -> 624408.93 | F17: =Модель!R73 -> 1171509 | G17: =Модель!U73 -> 1890211.2 | H17: =Модель!X73 -> 2766204.8 | I17: =Модель!AA73 -> 3804061.4 | J17: =Модель!AD73 -> 5096261.9 | K17: =Модель!AG73 -> 6593982.1 | L17: =Модель!AJ73 -> 8267030.4 | M17: =Модель!AM73 -> 10138854

Sheet Юнит-экономика
A1: Юнит-экономика: прибыль с банки и с заказа по каналам
A3: Продукт | B3: Розница | C3: Банка @1 000 | D3: Банка @5 000 | E3: Прибыль TikTok | F3: Маржа TikTok | G3: Прибыль Shopify | H3: Маржа Shopify | I3: Прибыль Amazon | J3: Маржа Amazon
A4: Colostrum | B4: =Допущения!$C$59 -> 39.95 | C4: =Допущения!$K$59*Допущения!$E$19 -> 7.97 | D4: =Допущения!$M$59*Допущения!$E$19 -> 7.67 | E4: =B4-C4-B4*(Допущения!$B$26+Допущения!$B$29+Допущения!$B$30)-Допущения!$D$59-Допущения!$B$39 -> 8.6005 | F4: =E4/B4 -> 0.2152816 | G4: =B4-C4-B4*(Допущения!$B$31+Допущения!$B$33)-Допущения!$B$32-Допущения!$D$59-Допущения!$B$39 -> 22.72245 | H4: =G4/B4 -> 0.56877222 | I4: =B4-C4-B4*(Допущения!$B$34+Допущения!$E$17)-Допущения!$E$59 -> 13.445 | J4: =I4/B4 -> 0.33654568
A5: Women's Probiotic | B5: =Допущения!$C$60 -> 34.95 | C5: =Допущения!$K$60*Допущения!$E$19 -> 7.44 | D5: =Допущения!$M$60*Допущения!$E$19 -> 6.94 | E5: =B5-C5-B5*(Допущения!$B$26+Допущения!$B$29+Допущения!$B$30)-Допущения!$D$60-Допущения!$B$39 -> 7.1805 | F5: =E5/B5 -> 0.20545064 | G5: =B5-C5-B5*(Допущения!$B$31+Допущения!$B$33)-Допущения!$B$32-Допущения!$D$60-Допущения!$B$39 -> 19.49745 | H5: =G5/B5 -> 0.55786695 | I5: =B5-C5-B5*(Допущения!$B$34+Допущения!$E$17)-Допущения!$E$60 -> 11.625 | J5: =I5/B5 -> 0.33261803
A6: Magnesium Glycinate | B6: =Допущения!$C$61 -> 29.95 | C6: =Допущения!$K$61*Допущения!$E$19 -> 4.61 | D6: =Допущения!$M$61*Допущения!$E$19 -> 4.11 | E6: =B6-C6-B6*(Допущения!$B$26+Допущения!$B$29+Допущения!$B$30)-Допущения!$D$61-Допущения!$B$39 -> 7.0605 | F6: =E6/B6 -> 0.2357429 | G6: =B6-C6-B6*(Допущения!$B$31+Допущения!$B$33)-Допущения!$B$32-Допущения!$D$61-Допущения!$B$39 -> 17.57245 | H6: =G6/B6 -> 0.58672621 | I6: =B6-C6-B6*(Допущения!$B$34+Допущения!$E$17)-Допущения!$E$61 -> 10.955 | J6: =I6/B6 -> 0.36577629
A7: Creatine | B7: =Допущения!$C$62 -> 29.95 | C7: =Допущения!$K$62*Допущения!$E$19 -> 6.35 | D7: =Допущения!$M$62*Допущения!$E$19 -> 6.05 | E7: =B7-C7-B7*(Допущения!$B$26+Допущения!$B$29+Допущения!$B$30)-Допущения!$D$62-Допущения!$B$39 -> 3.3205 | F7: =E7/B7 -> 0.11086811 | G7: =B7-C7-B7*(Допущения!$B$31+Допущения!$B$33)-Допущения!$B$32-Допущения!$D$62-Допущения!$B$39 -> 13.83245 | H7: =G7/B7 -> 0.46185142 | I7: =B7-C7-B7*(Допущения!$B$34+Допущения!$E$17)-Допущения!$E$62 -> 8.065 | J7: =I7/B7 -> 0.26928214
A9: Первая покупка
A10: Предложение | B10: Цена | C10: Товар @1 000 | D10: Прибыль TikTok | E10: Прибыль Shopify | F10: Доля заказов
A11: =Допущения!A67 -> Foundation: Colostrum + Magnesium | B11: =Допущения!B67 -> 59.95 | C11: =Допущения!E67*Допущения!$K$59*Допущения!$E$19+Допущения!F67*Допущения!$K$60*Допущения!$E$19+Допущения!G67*Допущения!$K$61*Допущения!$E$19+Допущения!H67*Допущения!$K$62*Допущения!$E$19 -> 12.58 | D11: =B11-C11-B11*(Допущения!$B$26+Допущения!$B$29+Допущения!$B$30)-Допущения!C67-Допущения!$B$39 -> 14.7905 | E11: =B11-C11-B11*(Допущения!$B$31+Допущения!$B$33)-Допущения!$B$32-Допущения!C67-Допущения!$B$39 -> 36.13245 | F11: =Допущения!D67 -> 0.35
A12: =Допущения!A68 -> Gut Duo: Colostrum + Probiotic | B12: =Допущения!B68 -> 64.95 | C12: =Допущения!E68*Допущения!$K$59*Допущения!$E$19+Допущения!F68*Допущения!$K$60*Допущения!$E$19+Допущения!G68*Допущения!$K$61*Допущения!$E$19+Допущения!H68*Допущения!$K$62*Допущения!$E$19 -> 15.41 | D12: =B12-C12-B12*(Допущения!$B$26+Допущения!$B$29+Допущения!$B$30)-Допущения!C68-Допущения!$B$39 -> 14.9105 | E12: =B12-C12-B12*(Допущения!$B$31+Допущения!$B$33)-Допущения!$B$32-Допущения!C68-Допущения!$B$39 -> 38.05745 | F12: =Допущения!D68 -> 0.1
A13: =Допущения!A69 -> The Daily Four | B13: =Допущения!B69 -> 114.95 | C13: =Допущения!E69*Допущения!$K$59*Допущения!$E$19+Допущения!F69*Допущения!$K$60*Допущения!$E$19+Допущения!G69*Допущения!$K$61*Допущения!$E$19+Допущения!H69*Допущения!$K$62*Допущения!$E$19 -> 26.37 | D13: =B13-C13-B13*(Допущения!$B$26+Допущения!$B$29+Допущения!$B$30)-Допущения!C69-Допущения!$B$39 -> 30.4505 | E13: =B13-C13-B13*(Допущения!$B$31+Допущения!$B$33)-Допущения!$B$32-Допущения!C69-Допущения!$B$39 -> 71.64745 | F13: =Допущения!D69 -> 0.05
A14: =Допущения!A70 -> Colostrum | B14: =Допущения!B70 -> 39.95 | C14: =Допущения!E70*Допущения!$K$59*Допущения!$E$19+Допущения!F70*Допущения!$K$60*Допущения!$E$19+Допущения!G70*Допущения!$K$61*Допущения!$E$19+Допущения!H70*Допущения!$K$62*Допущения!$E$19 -> 7.97 | D14: =B14-C14-B14*(Допущения!$B$26+Допущения!$B$29+Допущения!$B$30)-Допущения!C70-Допущения!$B$39 -> 8.6005 | E14: =B14-C14-B14*(Допущения!$B$31+Допущения!$B$33)-Допущения!$B$32-Допущения!C70-Допущения!$B$39 -> 22.72245 | F14: =Допущения!D70 -> 0.2
A15: =Допущения!A71 -> Women's Probiotic | B15: =Допущения!B71 -> 34.95 | C15: =Допущения!E71*Допущения!$K$59*Допущения!$E$19+Допущения!F71*Допущения!$K$60*Допущения!$E$19+Допущения!G71*Допущения!$K$61*Допущения!$E$19+Допущения!H71*Допущения!$K$62*Допущения!$E$19 -> 7.44 | D15: =B15-C15-B15*(Допущения!$B$26+Допущения!$B$29+Допущения!$B$30)-Допущения!C71-Допущения!$B$39 -> 7.1805 | E15: =B15-C15-B15*(Допущения!$B$31+Допущения!$B$33)-Допущения!$B$32-Допущения!C71-Допущения!$B$39 -> 19.49745 | F15: =Допущения!D71 -> 0.12
A16: =Допущения!A72 -> Magnesium Glycinate | B16: =Допущения!B72 -> 29.95 | C16: =Допущения!E72*Допущения!$K$59*Допущения!$E$19+Допущения!F72*Допущения!$K$60*Допущения!$E$19+Допущения!G72*Допущения!$K$61*Допущения!$E$19+Допущения!H72*Допущения!$K$62*Допущения!$E$19 -> 4.61 | D16: =B16-C16-B16*(Допущения!$B$26+Допущения!$B$29+Допущения!$B$30)-Допущения!C72-Допущения!$B$39 -> 7.0605 | E16: =B16-C16-B16*(Допущения!$B$31+Допущения!$B$33)-Допущения!$B$32-Допущения!C72-Допущения!$B$39 -> 17.57245 | F16: =Допущения!D72 -> 0.1
A17: =Допущения!A73 -> Creatine | B17: =Допущения!B73 -> 29.95 | C17: =Допущения!E73*Допущения!$K$59*Допущения!$E$19+Допущения!F73*Допущения!$K$60*Допущения!$E$19+Допущения!G73*Допущения!$K$61*Допущения!$E$19+Допущения!H73*Допущения!$K$62*Допущения!$E$19 -> 6.35 | D17: =B17-C17-B17*(Допущения!$B$26+Допущения!$B$29+Допущения!$B$30)-Допущения!C73-Допущения!$B$39 -> 3.3205 | E17: =B17-C17-B17*(Допущения!$B$31+Допущения!$B$33)-Допущения!$B$32-Допущения!C73-Допущения!$B$39 -> 13.83245 | F17: =Допущения!D73 -> 0.08
A18: Средний первый заказ | B18: =SUMPRODUCT(B11:B17,F11:F17) -> 50.8 | D18: =SUMPRODUCT(D11:D17,F11:F17) -> 11.7437 | E18: =SUMPRODUCT(E11:E17,F11:F17) -> 29.7825
A20: Подписка Shopify
A21: Подписка | B21: Цена в месяц | C21: Товар @1 000 | D21: Прибыль в месяц | E21: Прибыль в год | F21: Доля | G21: Жизнь подписчика, мес. | H21: Прибыль за жизнь (LTV)
A22: =Допущения!A78 -> Foundation | B22: =Допущения!B78 -> 54.95 | C22: =Допущения!E78*Допущения!$K$59*Допущения!$E$19+Допущения!F78*Допущения!$K$60*Допущения!$E$19+Допущения!G78*Допущения!$K$61*Допущения!$E$19+Допущения!H78*Допущения!$K$62*Допущения!$E$19 -> 12.58 | D22: =B22-C22-B22*(Допущения!$B$31+Допущения!$B$33)-Допущения!$B$32-Допущения!C78-Допущения!$B$39 -> 31.37745 | E22: =D22*12 -> 376.5294 | F22: =Допущения!D78 -> 0.6 | G22: =1/Допущения!$E$12 -> 10 | H22: =D22*G22 -> 313.7745
A23: =Допущения!A79 -> Gut Duo | B23: =Допущения!B79 -> 59.95 | C23: =Допущения!E79*Допущения!$K$59*Допущения!$E$19+Допущения!F79*Допущения!$K$60*Допущения!$E$19+Допущения!G79*Допущения!$K$61*Допущения!$E$19+Допущения!H79*Допущения!$K$62*Допущения!$E$19 -> 15.41 | D23: =B23-C23-B23*(Допущения!$B$31+Допущения!$B$33)-Допущения!$B$32-Допущения!C79-Допущения!$B$39 -> 33.30245 | E23: =D23*12 -> 399.6294 | F23: =Допущения!D79 -> 0.25 | G23: =1/Допущения!$E$12 -> 10 | H23: =D23*G23 -> 333.0245
A24: =Допущения!A80 -> The Daily Four, креатин раз в 2 мес. | B24: =Допущения!B80 -> 99.95 | C24: =Допущения!E80*Допущения!$K$59*Допущения!$E$19+Допущения!F80*Допущения!$K$60*Допущения!$E$19+Допущения!G80*Допущения!$K$61*Допущения!$E$19+Допущения!H80*Допущения!$K$62*Допущения!$E$19 -> 23.195 | D24: =B24-C24-B24*(Допущения!$B$31+Допущения!$B$33)-Допущения!$B$32-Допущения!C80-Допущения!$B$39 -> 61.55745 | E24: =D24*12 -> 738.6894 | F24: =Допущения!D80 -> 0.15 | G24: =1/Допущения!$E$12 -> 10 | H24: =D24*G24 -> 615.5745
A25: Средний подписчик | B25: =SUMPRODUCT(B22:B24,F22:F24) -> 62.95 | D25: =SUMPRODUCT(D22:D24,F22:F24) -> 36.3857 | E25: =SUMPRODUCT(E22:E24,F22:F24) -> 436.6284 | G25: =1/Допущения!$E$12 -> 10 | H25: =SUMPRODUCT(H22:H24,F22:F24) -> 363.857
A27: Ценность одного криейтора в месяц
A28: Заказов с роликов и органики | B28: =Допущения!$B$23*Допущения!$E$8*Допущения!$E$6*Допущения!$E$7*(1+Допущения!$E$9) -> 24
A29: Продаж на сумму | B29: =B28*Допущения!$B$74 -> 1219.2
A30: Заработок криейтора | B30: =B29*Допущения!$B$29 -> 365.76
A31: Заработок криейтора за ролик | B31: =B30/(Допущения!$B$23*Допущения!$E$8) -> 45.72
A32: Прибыль бренда с первых покупок | B32: =B28*D18 -> 281.8488
A33: Новых подписчиков | B33: =B28*(1+Допущения!$E$10)*Допущения!$E$11 -> 3.96
A34: Прибыль с этих подписчиков за их жизнь | B34: =B33*H25 -> 1440.8737

Sheet Сценарии
A1: Три сценария
A2: Снимок расчёта от 03.10.2026 по базовым вводным. После изменения допущений пересчитать: python3 analysis.py && python3 stress.py && python3 build_analysis_sheets.py
A4: Показатель | B4: Консервативный | C4: Базовый | D4: Оптимистичный
A5: Выручка год 1 | B5: 756747.27 | C5: 3677785.5 | D5: 11026826
A6: EBITDA год 1 | B6: 130137.95 | C6: 1188083.3 | D6: 4299386.1
A7: Выручка год 2 | B7: 1943383.1 | C7: 12077196 | D7: 43391967
A8: EBITDA год 2 | B8: 345631.75 | C8: 4600647.7 | D8: 19458257
A9: Выручка год 3 | B9: 2940438.7 | C9: 21146706 | D9: 72554176
A10: EBITDA год 3 | B10: 676029.56 | C10: 8729180 | D10: 35217566
A11: Чистая прибыль 3 года (сумма) | B11: 863849.44 | C11: 10888433 | D11: 44231407
A12: Подписчиков через 12 мес. | B12: 430.05174 | C12: 3893.9825 | D12: 16838.876
A13: Подписчиков через 24 мес. | B13: 912.83776 | C13: 10187.6 | D13: 49988.822
A14: Криейторов через 24 мес. | B14: 172 | C14: 294 | D14: 400
A15: Деньги на счёте через 12 мес. | B15: 61633.232 | C15: 624408.93 | D15: 2393394.4
A16: Минимум денег на счёте | B16: 245 | C16: -8323.2387 | D16: -42794.027
A17: Месяц темпа $1 млн EBITDA в год | B17: нет за 36 мес. | C17: 7 | D17: 3
A18: Окупаемость $25 000, месяц | B18: 6 | C18: 2 | D18: 2
A20: Что отличает сценарии
A21: Параметр | B21: Консервативный | C21: Базовый | D21: Оптимистичный
A22: Просмотров на ролик | B22: 3 500 | C22: 5 000 | D22: 7 000
A23: Конверсия | B23: 0,03% | C23: 0,05% | D23: 0,07%
A24: Доля вышедших роликов | B24: 60% | C24: 100% | D24: 100%
A25: Переход в подписку | B25: 12% | C25: 15% | D25: 20%
A26: Отток подписки | B26: 12% | C26: 10% | D26: 8%
A27: Новых криейторов в мес. | B27: 5-6 | C27: 10-12 | D27: 15-18
A28: Amazon, продаж в день на продукт | B28: 13 | C28: 30 | D28: 45
A29: Spark Ads, выручка на $1 рекламы | B29: 2 | C29: 3 | D29: 4
A30: Цена Vox | B30: +5% | C30: прайс | D30: прайс
A32: Деньги на старте: варианты финансирования (базовый сценарий)
A33: Вариант | B33: Минимум денег | C33: Месяц минимума | D33: EBITDA год 1
A34: Транш 2 = $5 000, запас 1,3 мес. | B34: -8323.2387 | C34: 2 | D34: 1188083.3
A35: Транш 2 = $5 000, запас 1,0 мес. | B35: -1157.7387 | C35: 2 | D35: 1188083.3
A36: Транш 2 = $14 000, запас 1,3 мес. | B36: 245 | C36: 0 | D36: 1188083.3
A37: Транш 2 = $21 000, запас 1,3 мес. | B37: 245 | C37: 0 | D37: 1188083.3

Sheet Чувствительность
A1: Чувствительность и стресс-тесты
A2: Снимок расчёта от 03.10.2026 по базовым вводным. После изменения допущений пересчитать: python3 analysis.py && python3 stress.py && python3 build_analysis_sheets.py
A4: Торнадо: каждый параметр отдельно, остальное по базе
A5: Параметр | B5: Плохое значение | C5: Хорошее значение | D5: EBITDA год 1, плохо | E5: EBITDA год 1, хорошо | F5: EBITDA год 2, плохо | G5: EBITDA год 2, хорошо | H5: Размах год 2
A6: Конверсия просмотра в заказ | B6: 0.0003 | C6: 0.0007 | D6: 754570.91 | E6: 1630402.9 | F6: 2892576.2 | G6: 6294933.3 | H6: 3402357.1
A7: Просмотров на ролик | B7: 3500 | C7: 7000 | D7: 860953.76 | E7: 1630402.9 | F7: 3322165.9 | G7: 6294933.3 | H7: 2972767.4
A8: Новых криейторов в мес. 3-12 | B8: 5 | C8: 15 | D8: 952202.31 | E8: 1424715.5 | F8: 3553357.7 | G8: 5644751.3 | H8: 2091393.6
A9: Доля вышедших роликов | B9: 0.6 | C9: 1 | D9: 754570.91 | E9: 1188083.3 | F9: 2892576.2 | G9: 4600647.7 | H9: 1708071.5
A10: Переход в подписку | B10: 0.12 | C10: 0.2 | D10: 1052786.4 | E10: 1409732.9 | F10: 3972667.1 | G10: 5651050.1 | H10: 1678383
A11: Новых криейторов в мес. с 13-го | B11: 6 | C11: 18 | D11: 1188083.3 | E11: 1188083.3 | F11: 4145540.9 | G11: 5059628 | H11: 914087.03
A12: Органика | B12: 0.1 | C12: 0.3 | D12: 1095859.3 | E12: 1276662.2 | F12: 4247420 | G12: 4958997.1 | H12: 711577.1
A13: Spark Ads: ROAS | B13: 2 | C13: 4 | D13: 1107948.6 | E13: 1264925 | F13: 4254976.7 | G13: 4952828.7 | H13: 697852.01
A14: Отток подписки | B14: 0.12 | C14: 0.08 | D14: 1156405.2 | E14: 1220556.9 | F14: 4331392.5 | G14: 4920566.4 | H14: 589173.84
A15: Amazon: продаж в день на продукт | B15: 13 | C15: 45 | D15: 1077048.1 | E15: 1282787.9 | F15: 4304478.7 | G15: 4869139.1 | H15: 564660.45
A16: Комиссия криейтора | B16: 0.35 | C16: 0.25 | D16: 1100814 | E16: 1275352.6 | F16: 4378357.1 | G16: 4822938.3 | H16: 444581.28
A17: Цена Vox | B17: 1.1 | C17: 0.95 | D17: 1111419.2 | E17: 1226415.4 | F17: 4363270.1 | G17: 4719336.5 | H17: 356066.45
A18: Amazon: доля рекламы | B18: 0.2 | C18: 0.12 | D18: 1156061.2 | E18: 1207296.6 | F18: 4497719.4 | G18: 4662404.7 | H18: 164685.31
A20: Стресс-тесты
A21: Событие | B21: EBITDA год 1 | C21: EBITDA год 2 | D21: EBITDA год 3 | E21: Минимум денег | F21: Темп $1 млн, месяц
A22: Базовый сценарий | B22: 1188083.3 | C22: 4600647.7 | D22: 8729180 | E22: -8323.2387 | F22: 7
A23: TikTok Shop заблокирован на 2 месяца (март-апрель 2027) | B23: 964428.11 | C23: 4478670.5 | D23: 8694880.2 | E23: -8323.2387 | F23: 8
A24: Vox не отгрузил товар: месяц без продаж (февраль 2027) | B24: 1145351.4 | C24: 4600647.7 | D24: 8729180 | E24: -8323.2387 | F24: 7
A25: Amazon не дал допуск к категории | B25: 965450.38 | C25: 3874085.2 | D25: 7693194.7 | E25: -8323.2387 | F25: 8
A26: Продукт не цепляет: конверсия 0,02% | B26: 542945.43 | C26: 2040521.9 | D26: 3891315.5 | E26: 245 | F26: 11
A27: Криейторов не прибавляется: 50 весь срок | B27: 724338.12 | C27: 1590577.4 | D27: 2034233.7 | E27: -4644.7387 | F27: 9
A28: Цены Vox +15% | B28: 1073087.2 | C28: 4244581.3 | D28: 8110459.8 | E28: -13149.34 | F28: 7
A29: Spark Ads не окупаются: ROAS 1,5 | B29: 1068999.2 | C29: 4080301.4 | D29: 7739418 | E29: -8323.2387 | F29: 7
A30: TikTok оставил комиссию 6% | B30: 1222991 | C30: 4689564 | D30: 8872162.4 | E30: -7587.1467 | F30: 7
A31: Подписка не работает: переход 5%, отток 15% | B31: 714769.16 | C31: 2289581.6 | D31: 4021051.4 | E31: -5535.5891 | F31: 9
A32: Всё плохо сразу: конверсия 0,03%, 60% роликов, без Amazon, отток 12% | B32: 231627.78 | C32: 876943.57 | D32: 1847410.3 | E32: 245 | F32: 21
A34: Точки безубыточности по конверсии (без Amazon, остальное по базе)
A35: EBITDA года 1 больше нуля при конверсии от | B35: 4.0972081e-05
A36: EBITDA года 2 от $1 млн при конверсии от | B36: 0.0001588523
A37: EBITDA года 1 от $1 млн при конверсии от | B37: 0.00051634169
A38: База: 0,05%. Запас прочности по конверсии большой: бизнес остаётся прибыльным, даже если конверсия в 10 раз ниже базы.

Sheet Монте-Карло
A1: Монте-Карло: 5000 случайных прогонов модели
A2: Снимок расчёта от 03.10.2026 по базовым вводным. После изменения допущений пересчитать: python3 analysis.py && python3 stress.py && python3 build_analysis_sheets.py Сид 42.
A4: Распределения вводных (треугольные: минимум, наиболее вероятное, максимум)
A5: Параметр | B5: Минимум | C5: Наиболее вероятное | D5: Максимум
A6: Просмотров на ролик | B6: 3000 | C6: 5000 | D6: 8000
A7: Конверсия | B7: 0.0002 | C7: 0.0005 | D7: 0.0008
A8: Доля вышедших роликов | B8: 0.5 | C8: 0.85 | D8: 1
A9: Органика | B9: 0.05 | C9: 0.2 | D9: 0.3
A10: Прямые заказы Shopify | B10: 0.05 | C10: 0.1 | D10: 0.15
A11: Переход в подписку | B11: 0.08 | C11: 0.15 | D11: 0.22
A12: Отток подписки | B12: 0.07 | C12: 0.1 | D12: 0.15
A13: Новых криейторов мес. 3-12 | B13: 4 | C13: 10 | D13: 15
A14: Новых криейторов с 13-го | B14: 5 | C14: 12 | D14: 18
A15: Amazon, продаж в день на продукт | B15: 8 | C15: 30 | D15: 45
A16: Amazon, прирост в день в мес. | B16: 0 | C16: 1.5 | D16: 2.5
A17: Amazon, доля рекламы | B17: 0.12 | C17: 0.15 | D17: 0.25
... A19: Множитель цены Vox | B19: 0.95 | C19: 1 | D19: 1.15
A21: Результаты
A22: Показатель | B22: P10 (плохой из 10) | C22: P50 (медиана) | D22: P90 (хороший из 10) | E22: Среднее
A23: Выручка год 1 | B23: 1973048.4 | C23: 2922730.7 | D23: 4325167.1 | E23: 3068876
A24: EBITDA год 1 | B24: 547050.6 | C24: 875237.98 | D24: 1390899.7 | E24: 934413.09
A25: Выручка год 2 | B25: 6257575.7 | C25: 9453852.3 | D25: 14281265 | E25: 9924719.6
A26: EBITDA год 2 | B26: 2008397.7 | C26: 3342876.3 | D26: 5407218.6 | E26: 3568252
A27: Выручка год 3 | B27: 10445827 | C27: 16176290 | D27: 24664742 | E27: 17008093
A28: EBITDA год 3 | B28: 3752836.9 | C28: 6309639.6 | D28: 10235314 | E28: 6724560.2
A29: Подписчиков через 24 мес. | B29: 4132.3157 | C29: 7443.7864 | D29: 12750.622 | E29: 8044.0474
A30: Минимум денег на счёте | B30: -15508.117 | C30: -3151.2067 | D30: 245 | E30: -5584.3987
A32: Вероятности
A33: EBITDA года 1 в минусе | B33: 0
A34: EBITDA года 1 от $1 млн | B34: 0.3618
A35: EBITDA года 2 от $1 млн | B35: 0.9996
A36: Темп $1 млн EBITDA в год наступает в первые 24 месяца | B36: 1
A37: Денег на старте не хватает без доплаты | B37: 0.6772
A38: Не хватает больше $10 000 | B38: 0.2256
A39: Нужная доплата с вероятностью 90% | B39: 15508.117
A40: Месяц темпа $1 млн: медиана | B40: 8
A41: Месяц темпа $1 млн: P10-P90 | B41: 6-11
A43: Распределение EBITDA года 2
A44: Диапазон | B44: Доля прогонов
A45: убыток | B45: 0
...

Sheet Риски
A1: Реестр рисков
A2: Вероятность это оценка на 03.10.2026. Ущерб: потеря EBITDA года 1 из стресс-тестов и торнадо. Ожидаемый ущерб = вероятность × ущерб.
A4: Риск | B4: Вероятность | C4: Ущерб, EBITDA год 1 | D4: Ожидаемый ущерб | E4: Ранний сигнал (KPI) | F4: Что делаем | G4: Кто
A5: Криейторы не выпускают 8 роликов | B5: 0.5 | C5: 433512.4 | D5: =B5*C5 -> 216756.2 | E5: меньше 2 роликов в неделю на криейтора | F5: еженедельный учёт, замена неактивных, бонус лучшим | G5: Полина
A6: Конверсия ниже базы (0,03%) | B6: 0.3 | C6: 433512.4 | D6: =B6*C6 -> 130053.72 | E6: меньше 0,4 заказа на 1 000 просмотров в первые 2 недели | F6: тест хуков, Flip the jar, стартовая скидка | G6: владелец, Полина
A7: Подписка слабее плана | B7: 0.25 | C7: 473314.16 | D7: =B7*C7 -> 118328.54 | E7: переход в подписку меньше 10% за первые 60 дней | F7: письма день 0, 7, 25, скидка на первую подписку, вкладыш | G7: Claude, владелец
A8: Amazon не даёт допуск к добавкам | B8: 0.2 | C8: 222632.94 | D8: =B8*C8 -> 44526.587 | E8: нет допуска к 15.02.2027 | F8: COA из лаборатории ISO 17025 в январе, Brand Registry по заявке USPTO | G8: владелец
A9: Криейторов не прибавляется | B9: 0.2 | C9: 463745.19 | D9: =B9*C9 -> 92749.038 | E9: меньше 8 новых в месяц | F9: аутрич 100 в неделю, менеджер криейторов с 5-го месяца | G9: Полина
A10: TikTok Shop блокирует магазин на 2 месяца | B10: 0.1 | C10: 223655.2 | D10: =B10*C10 -> 22365.52 | E10: страйки за заявления, жалобы | F10: этикетка завода дословно, без заявлений о болезни, Shopify и Amazon как опора | G10: Claude
A11: Цены Vox растут на 15% | B11: 0.15 | C11: 114996.11 | D11: =B11*C11 -> 17249.417 | E11: новый прайс Vox | F11: годовой объём под цену, SMP вторым источником | G11: владелец
A12: Vox срывает отгрузку на месяц | B12: 0.15 | C12: 42731.894 | D12: =B12*C12 -> 6409.7841 | E12: срок перезаказа больше 15 рабочих дней | F12: запас 1,3 месяца, подтверждение мощности в мае 2027, SMP в резерве | G12: Claude
A13: Денег на товар не хватает в декабре | B13: 0.85 | C13: 8593.7 | D13: =B13*C13 -> 7304.645 | E13: деньги на счёте меньше $3 000 | F13: второй транш $21 000 или перезаказ дважды в месяц | G13: владелец
A14: Задержка выплат TikTok новому продавцу | B14: 0.3 | C14: 0 | D14: =B14*C14 -> 0 | E14: выплата позже 14 дней после доставки | F14: резерв в кассе, Shopify как быстрый канал денег | G14: владелец
A15: Претензия по качеству или отзыв партии | B15: 0.05 | C15: 50000 | D15: =B15*C15 -> 2500 | E15: жалобы на вкус, комки, реакции | F15: COA каждой партии, страховка ответственности, этикетка завода | G15: владелец
A16: Нагрузка на владельца и Полину | B16: 0.4 | C16: 0 | D16: =B16*C16 -> 0 | E16: ответ клиенту дольше 24 часов | F16: найм с 5-6-го месяца по плану команды | G16: владелец
A17: Итого ожидаемый ущерб | D17: =SUM(D5:D16) -> 658243.45

Sheet Допущения
A1: The Aldera · 518 GROUP LLC · Финансовая модель · допущения
A2: Синий шрифт: вводные, их можно менять. Чёрный: формулы. Жёлтая заливка: ключевые рычаги. Модель пересчитывается сама.
A3: Сценарий: 1 консервативный, 2 базовый, 3 оптимистичный | B3: 2
A5: Параметр сценария | B5: Консерв. | C5: Базовый | D5: Оптим. | E5: Активное | F5: Пояснение
A6: Просмотров на ролик | B6: 3500 | C6: 5000 | D6: 7000 | E6: =CHOOSE($B$3,B6,C6,D6) -> 5000 | F6: Средние просмотры ролика микро-криейтора
A7: Конверсия просмотра в заказ | B7: 0.0003 | C7: 0.0005 | D7: 0.0007 | E7: =CHOOSE($B$3,B7,C7,D7) -> 0.0005 | F7: Доля просмотров, которая становится заказом
A8: Доля роликов, которые реально выходят | B8: 0.6 | C8: 1 | D8: 1 | E8: =CHOOSE($B$3,B8,C8,D8) -> 1 | F8: 8 роликов по договору; база по условию владельца
A9: Органика и поиск сверху | B9: 0.1 | C9: 0.2 | D9: 0.3 | E9: =CHOOSE($B$3,B9,C9,D9) -> 0.2 | F9: Заказы без ролика: поиск, профиль, повторный показ
A10: Прямые заказы на Shopify, доля от TikTok | B10: 0.05 | C10: 0.1 | D10: 0.15 | E10: =CHOOSE($B$3,B10,C10,D10) -> 0.1 | F10: Покупатели из TikTok, которые идут на сайт
A11: Переход первых покупателей в подписку | B11: 0.12 | C11: 0.15 | D11: 0.2 | E11: =CHOOSE($B$3,B11,C11,D11) -> 0.15 | F11: Главный рычаг модели
A12: Отток подписки в месяц | B12: 0.12 | C12: 0.1 | D12: 0.08 | E12: =CHOOSE($B$3,B12,C12,D12) -> 0.1 | F12: Обычная цифра для подписки на добавки около 10%
A13: Новых криейторов в месяц, мес. 3-12 | B13: 5 | C13: 10 | D13: 15 | E13: =CHOOSE($B$3,B13,C13,D13) -> 10 | F13: Старт 50 криейторов
A14: Новых криейторов в месяц, с 13-го | B14: 6 | C14: 12 | D14: 18 | E14: =CHOOSE($B$3,B14,C14,D14) -> 12
A15: Amazon: продаж в день на продукт после разгона | B15: 13 | C15: 30 | D15: 45 | E15: =CHOOSE($B$3,B15,C15,D15) -> 30 | F15: Достигается через N месяцев разгона
A16: Amazon: прирост в день на продукт в месяц после разгона | B16: 0.5 | C16: 1.5 | D16: 2.5 | E16: =CHOOSE($B$3,B16,C16,D16) -> 1.5
A17: Amazon: реклама PPC, доля цены | B17: 0.2 | C17: 0.15 | D17: 0.12 | E17: =CHOOSE($B$3,B17,C17,D17) -> 0.15 | F17: Половина продаж через рекламу при ACoS 24-40%
A18: Spark Ads: выручка на $1 рекламы (ROAS) | B18: 2 | C18: 3 | D18: 4 | E18: =CHOOSE($B$3,B18,C18,D18) -> 3 | F18: Реклама идёт только на ролики с доказанной конверсией
A19: Множитель себестоимости Vox | B19: 1.05 | C19: 1 | D19: 1 | E19: =CHOOSE($B$3,B19,C19,D19) -> 1 | F19: Рост цен поставщика
A21: Постоянные допущения
A22: Криейторов на старте | B22: 50 | C22: Решение владельца
A23: Роликов на криейтора в месяц по договору | B23: 8 | C23: Решение владельца: 8 роликов за 30%
A24: Потолок числа криейторов | B24: 400 | C24: Предел для одного менеджера-отдела
A25: Доля первого месяца (продажи с 20.11) | B25: 0.36666667 | C25: 11 дней из 30
A26: TikTok Shop: комиссия площадки | B26: 0.08 | C26: С 04.08.2026 TikTok поднял ставку с 6% до 8% для большинства непищевых категорий. Ставку для добавок проверить в Seller Center
A27: Spark Ads на выстрелившие ролики, доля органической выручки TikTok | B27: 0.1 | C27: Решение владельца 03.10: платная реклама только на ролики, которые уже выстрелили
A28: Spark Ads: с месяца модели | B28: 4 | C28: Февраль 2027: после декабрьского провала денег
A29: Комиссия криейтора | B29: 0.3 | C29: Решение владельца
A30: TikTok: возвраты, доля выручки | B30: 0.03
A31: Shopify Payments: процент | B31: 0.029 | C31: Тариф Shopify Basic
A32: Shopify Payments: за транзакцию | B32: 0.3
A33: Shopify: возвраты, доля выручки | B33: 0.02
A34: Amazon: комиссия за продажу | B34: 0.15 | C34: Категория Health & Household
A35: Amazon: месяц старта (1 = ноябрь 2026) | B35: 5 | C35: Март 2027, после Brand Registry и допуска
A36: Amazon: продаж в день на продукт в первый месяц | B36: 5
A37: Amazon: месяцев разгона | B37: 6
A38: Число продуктов | B38: 4
A39: Склад-отправщик, за заказ TikTok и Shopify | B39: 2.5 | C39: Пик-пак 3PL во Флориде, оценка
A40: Доля выплат TikTok и Amazon, приходящая в следующем месяце | B40: 0.5 | C40: Выплаты после доставки и раз в две недели
A41: Запас товара после перезаказа, месяцев продаж | B41: 1.3 | C41: Политика перезаказа
A42: Минимальный заказ Vox, банок | B42: 150 | C42: Прайс Vox 2026 Q3
...

Sheet Модель
A1: Помесячная модель, 36 месяцев (ноябрь 2026 - октябрь 2029)
A2: Месяц модели | C2: 0 | D2: =C2+1 -> 1 | E2: =D2+1 -> 2 | F2: =E2+1 -> 3 | G2: =F2+1 -> 4 | H2: =G2+1 -> 5 | I2: =H2+1 -> 6 | J2: =I2+1 -> 7 | K2: =J2+1 -> 8 | ... AM2: =AL2+1 -> 36
A3: Месяц | C3: =DATE(2026,10+C2,1) -> 46296 | D3: =DATE(2026,10+D2,1) -> 46327 | E3: =DATE(2026,10+E2,1) -> 46357 | F3: =DATE(2026,10+F2,1) -> 46388 | G3: =DATE(2026,10+G2,1) -> 46419 | H3: =DATE(2026,10+H2,1) -> 46447 | I3: =DATE(2026,10+I2,1) -> 46478 | J3: =DATE(2026,10+J2,1) -> 46508 | ... AM3: =DATE(2026,10+AM2,1) -> 47392
A4: Календарный месяц | C4: =MONTH(C3) -> 10 | D4: =MONTH(D3) -> 11 | E4: =MONTH(E3) -> 12 | F4: =MONTH(F3) -> 1 | G4: =MONTH(G3) -> 2 | H4: =MONTH(H3) -> 3 | I4: =MONTH(I3) -> 4 | J4: =MONTH(J3) -> 5 | ... AM4: =MONTH(AM3) -> 10
A5: Год модели | C5: =IF(C2=0,0,INT((C2-1)/12)+1) -> 0 | D5: =IF(D2=0,0,INT((D2-1)/12)+1) -> 1 | E5: =IF(E2=0,0,INT((E2-1)/12)+1) -> 1 | F5: =IF(F2=0,0,INT((F2-1)/12)+1) -> 1 | G5: =IF(G2=0,0,INT((G2-1)/12)+1) -> 1 | H5: =IF(H2=0,0,INT((H2-1)/12)+1) -> 1 | I5: =IF(I2=0,0,INT((I2-1)/12)+1) -> 1 | J5: =IF(J2=0,0,INT((J2-1)/12)+1) -> 1 | ... AM5: =IF(AM2=0,0,INT((AM2-1)/12)+1) -> 3
A6: Доля месяца | C6: =IF(C2=0,0,IF(C2=1,Допущения!$B$25,1)) -> 0 | D6: =IF(D2=0,0,IF(D2=1,Допущения!$B$25,1)) -> 0.36666667 | E6: =IF(E2=0,0,IF(E2=1,Допущения!$B$25,1)) -> 1 | F6: =IF(F2=0,0,IF(F2=1,Допущения!$B$25,1)) -> 1 | G6: =IF(G2=0,0,IF(G2=1,Допущения!$B$25,1)) -> 1 | H6: =IF(H2=0,0,IF(H2=1,Допущения!$B$25,1)) -> 1 | I6: =IF(I2=0,0,IF(I2=1,Допущения!$B$25,1)) -> 1 | J6: =IF(J2=0,0,IF(J2=1,Допущения!$B$25,1)) -> 1 | ... AM6: =IF(AM2=0,0,IF(AM2=1,Допущения!$B$25,1)) -> 1
A7: Сезонность | C7: =INDEX(Допущения!$B$87:$B$98,C4) -> 1 | D7: =INDEX(Допущения!$B$87:$B$98,D4) -> 1.15 | E7: =INDEX(Допущения!$B$87:$B$98,E4) -> 1.15 | F7: =INDEX(Допущения!$B$87:$B$98,F4) -> 1.1 | G7: =INDEX(Допущения!$B$87:$B$98,G4) -> 1 | H7: =INDEX(Допущения!$B$87:$B$98,H4) -> 1 | I7: =INDEX(Допущения!$B$87:$B$98,I4) -> 1 | J7: =INDEX(Допущения!$B$87:$B$98,J4) -> 1 | ... AM7: =INDEX(Допущения!$B$87:$B$98,AM4) -> 1
A8: Воронка
A9: Активных криейторов | C9: 0 | D9: =IF(D2<=2,Допущения!$B$22,IF(D2<=12,C9+Допущения!$E$13,MIN(Допущения!$B$24,C9+Допущения!$E$14))) -> 50 | E9: =IF(E2<=2,Допущения!$B$22,IF(E2<=12,D9+Допущения!$E$13,MIN(Допущения!$B$24,D9+Допущения!$E$14))) -> 50 | F9: =IF(F2<=2,Допущения!$B$22,IF(F2<=12,E9+Допущения!$E$13,MIN(Допущения!$B$24,E9+Допущения!$E$14))) -> 60 | G9: =IF(G2<=2,Допущения!$B$22,IF(G2<=12,F9+Допущения!$E$13,MIN(Допущения!$B$24,F9+Допущения!$E$14))) -> 70 | H9: =IF(H2<=2,Допущения!$B$22,IF(H2<=12,G9+Допущения!$E$13,MIN(Допущения!$B$24,G9+Допущения!$E$14))) -> 80 | I9: =IF(I2<=2,Допущения!$B$22,IF(I2<=12,H9+Допущения!$E$13,MIN(Допущения!$B$24,H9+Допущения!$E$14))) -> 90 | J9: =IF(J2<=2,Допущения!$B$22,IF(J2<=12,I9+Допущения!$E$13,MIN(Допущения!$B$24,I9+Допущения!$E$14))) -> 100 | K9: =IF(K2<=2,Допущения!$B$22,IF(K2<=12,J9+Допущения!$E$13,MIN(Допущения!$B$24,J9+Допущения!$E$14))) -> 110 | ... AM9: =IF(AM2<=2,Допущения!$B$22,IF(AM2<=12,AL9+Допущения!$E$13,MIN(Допущения!$B$24,AL9+Допущения!$E$14))) -> 400
A10: Роликов вышло | C10: =C9*Допущения!$B$23*Допущения!$E$8*C6 -> 0 | D10: =D9*Допущения!$B$23*Допущения!$E$8*D6 -> 146.66667 | E10: =E9*Допущения!$B$23*Допущения!$E$8*E6 -> 400 | F10: =F9*Допущения!$B$23*Допущения!$E$8*F6 -> 480 | G10: =G9*Допущения!$B$23*Допущения!$E$8*G6 -> 560 | H10: =H9*Допущения!$B$23*Допущения!$E$8*H6 -> 640 | I10: =I9*Допущения!$B$23*Допущения!$E$8*I6 -> 720 | J10: =J9*Допущения!$B$23*Допущения!$E$8*J6 -> 800 | ... AM10: =AM9*Допущения!$B$23*Допущения!$E$8*AM6 -> 3200
A11: Просмотров | C11: =C10*Допущения!$E$6 -> 0 | D11: =D10*Допущения!$E$6 -> 733333.33 | E11: =E10*Допущения!$E$6 -> 2000000 | F11: =F10*Допущения!$E$6 -> 2400000 | G11: =G10*Допущения!$E$6 -> 2800000 | H11: =H10*Допущения!$E$6 -> 3200000 | I11: =I10*Допущения!$E$6 -> 3600000 | J11: =J10*Допущения!$E$6 -> 4000000 | ... AM11: =AM10*Допущения!$E$6 -> 16000000
A12: Заказы TikTok (первые покупки) | C12: =C11*Допущения!$E$7*(1+Допущения!$E$9)*C7*(1+IF(C2>=Допущения!$B$28,Допущения!$B$27,0)*Допущения!$E$18) -> 0 | D12: =D11*Допущения!$E$7*(1+Допущения!$E$9)*D7*(1+IF(D2>=Допущения!$B$28,Допущения!$B$27,0)*Допущения!$E$18) -> 506 | E12: =E11*Допущения!$E$7*(1+Допущения!$E$9)*E7*(1+IF(E2>=Допущения!$B$28,Допущения!$B$27,0)*Допущения!$E$18) -> 1380 | F12: =F11*Допущения!$E$7*(1+Допущения!$E$9)*F7*(1+IF(F2>=Допущения!$B$28,Допущения!$B$27,0)*Допущения!$E$18) -> 1584 | G12: =G11*Допущения!$E$7*(1+Допущения!$E$9)*G7*(1+IF(G2>=Допущения!$B$28,Допущения!$B$27,0)*Допущения!$E$18) -> 2184 | H12: =H11*Допущения!$E$7*(1+Допущения!$E$9)*H7*(1+IF(H2>=Допущения!$B$28,Допущения!$B$27,0)*Допущения!$E$18) -> 2496 | I12: =I11*Допущения!$E$7*(1+Допущения!$E$9)*I7*(1+IF(I2>=Допущения!$B$28,Допущения!$B$27,0)*Допущения!$E$18) -> 2808 | J12: =J11*Допущения!$E$7*(1+Допущения!$E$9)*J7*(1+IF(J2>=Допущения!$B$28,Допущения!$B$27,0)*Допущения!$E$18) -> 3120 | ... AM12: =AM11*Допущения!$E$7*(1+Допущения!$E$9)*AM7*(1+IF(AM2>=Допущения!$B$28,Допущения!$B$27,0)*Допущения!$E$18) -> 12480
A13: Заказы Shopify прямые (первые) | C13: =C12*Допущения!$E$10 -> 0 | D13: =D12*Допущения!$E$10 -> 50.6 | E13: =E12*Допущения!$E$10 -> 138 | F13: =F12*Допущения!$E$10 -> 158.4 | G13: =G12*Допущения!$E$10 -> 218.4 | H13: =H12*Допущения!$E$10 -> 249.6 | I13: =I12*Допущения!$E$10 -> 280.8 | J13: =J12*Допущения!$E$10 -> 312 | ... AM13: =AM12*Допущения!$E$10 -> 1248
A14: Новые подписчики | C14: =(C12+C13)*Допущения!$E$11 -> 0 | D14: =(D12+D13)*Допущения!$E$11 -> 83.49 | E14: =(E12+E13)*Допущения!$E$11 -> 227.7 | F14: =(F12+F13)*Допущения!$E$11 -> 261.36 | G14: =(G12+G13)*Допущения!$E$11 -> 360.36 | H14: =(H12+H13)*Допущения!$E$11 -> 411.84 | I14: =(I12+I13)*Допущения!$E$11 -> 463.32 | J14: =(J12+J13)*Допущения!$E$11 -> 514.8 | ... AM14: =(AM12+AM13)*Допущения!$E$11 -> 2059.2
A15: Подписчиков на конец месяца | C15: 0 | D15: =C15*(1-Допущения!$E$12)+D14 -> 83.49 | E15: =D15*(1-Допущения!$E$12)+E14 -> 302.841 | F15: =E15*(1-Допущения!$E$12)+F14 -> 533.9169 | G15: =F15*(1-Допущения!$E$12)+G14 -> 840.88521 | H15: =G15*(1-Допущения!$E$12)+H14 -> 1168.6367 | I15: =H15*(1-Допущения!$E$12)+I14 -> 1515.093 | J15: =I15*(1-Допущения!$E$12)+J14 -> 1878.3837 | K15: =J15*(1-Допущения!$E$12)+K14 -> 2256.8253 | ... AM15: =AL15*(1-Допущения!$E$12)+AM14 -> 17004.955
A16: Заказы подписки (списание) | C16: 0 | D16: =C15 -> 0 | E16: =D15 -> 83.49 | F16: =E15 -> 302.841 | G16: =F15 -> 533.9169 | H16: =G15 -> 840.88521 | I16: =H15 -> 1168.6367 | J16: =I15 -> 1515.093 | K16: =J15 -> 1878.3837 | ... AM16: =AL15 -> 16606.395
A17: Amazon: продаж в день на продукт | C17: =IF(C2<Допущения!$B$35,0,IF(C2-Допущения!$B$35<=Допущения!$B$37,Допущения!$B$36+(Допущения!$E$15-Допущения!$B$36)*(C2-Допущения!$B$35)/Допущения!$B$37,Допущения!$E$15+Допущения!$E$16*(C2-Допущения!$B$35-Допущения!$B$37))) -> 0 | D17: =IF(D2<Допущения!$B$35,0,IF(D2-Допущения!$B$35<=Допущения!$B$37,Допущения!$B$36+(Допущения!$E$15-Допущения!$B$36)*(D2-Допущения!$B$35)/Допущения!$B$37,Допущения!$E$15+Допущения!$E$16*(D2-Допущения!$B$35-Допущения!$B$37))) -> 0 | E17: =IF(E2<Допущения!$B$35,0,IF(E2-Допущения!$B$35<=Допущения!$B$37,Допущения!$B$36+(Допущения!$E$15-Допущения!$B$36)*(E2-Допущения!$B$35)/Допущения!$B$37,Допущения!$E$15+Допущения!$E$16*(E2-Допущения!$B$35-Допущения!$B$37))) -> 0 | F17: =IF(F2<Допущения!$B$35,0,IF(F2-Допущения!$B$35<=Допущения!$B$37,Допущения!$B$36+(Допущения!$E$15-Допущения!$B$36)*(F2-Допущения!$B$35)/Допущения!$B$37,Допущения!$E$15+Допущения!$E$16*(F2-Допущения!$B$35-Допущения!$B$37))) -> 0 | G17: =IF(G2<Допущения!$B$35,0,IF(G2-Допущения!$B$35<=Допущения!$B$37,Допущения!$B$36+(Допущения!$E$15-Допущения!$B$36)*(G2-Допущения!$B$35)/Допущения!$B$37,Допущения!$E$15+Допущения!$E$16*(G2-Допущения!$B$35-Допущения!$B$37))) -> 0 | H17: =IF(H2<Допущения!$B$35,0,IF(H2-Допущения!$B$35<=Допущения!$B$37,Допущения!$B$36+(Допущения!$E$15-Допущения!$B$36)*(H2-Допущения!$B$35)/Допущения!$B$37,Допущения!$E$15+Допущения!$E$16*(H2-Допущения!$B$35-Допущения!$B$37))) -> 5 | I17: =IF(I2<Допущения!$B$35,0,IF(I2-Допущения!$B$35<=Допущения!$B$37,Допущения!$B$36+(Допущения!$E$15-Допущения!$B$36)*(I2-Допущения!$B$35)/Допущения!$B$37,Допущения!$E$15+Допущения!$E$16*(I2-Допущения!$B$35-Допущения!$B$37))) -> 9.1666667 | J17: =IF(J2<Допущения!$B$35,0,IF(J2-Допущения!$B$35<=Допущения!$B$37,Допущения!$B$36+(Допущения!$E$15-Допущения!$B$36)*(J2-Допущения!$B$35)/Допущения!$B$37,Допущения!$E$15+Допущения!$E$16*(J2-Допущения!$B$35-Допущения!$B$37))) -> 13.333333 | ... AM17: =IF(AM2<Допущения!$B$35,0,IF(AM2-Допущения!$B$35<=Допущения!$B$37,Допущения!$B$36+(Допущения!$E$15-Допущения!$B$36)*(AM2-Допущения!$B$35)/Допущения!$B$37,Допущения!$E$15+Допущения!$E$16*(AM2-Допущения!$B$35-Допущения!$B$37))) -> 67.5
A18: Заказы Amazon | C18: =C17*Допущения!$B$38*30.4 -> 0 | D18: =D17*Допущения!$B$38*30.4 -> 0 | E18: =E17*Допущения!$B$38*30.4 -> 0 | F18: =F17*Допущения!$B$38*30.4 -> 0 | G18: =G17*Допущения!$B$38*30.4 -> 0 | H18: =H17*Допущения!$B$38*30.4 -> 608 | I18: =I17*Допущения!$B$38*30.4 -> 1114.6667 | J18: =J17*Допущения!$B$38*30.4 -> 1621.3333 | ... AM18: =AM17*Допущения!$B$38*30.4 -> 8208
A19: Всего заказов | C19: =C12+C13+C16+C18 -> 0 | D19: =D12+D13+D16+D18 -> 556.6 | E19: =E12+E13+E16+E18 -> 1601.49 | F19: =F12+F13+F16+F18 -> 2045.241 | G19: =G12+G13+G16+G18 -> 2936.3169 | H19: =H12+H13+H16+H18 -> 4194.4852 | I19: =I12+I13+I16+I18 -> 5372.1034 | J19: =J12+J13+J16+J18 -> 6568.4264 | ... AM19: =AM12+AM13+AM16+AM18 -> 38542.395
A20: Банок продано
A21: Банок: Colostrum | C21: =(C12+C13)*Допущения!$E$74+C16*Допущения!$E$81+C18*Допущения!$F$59 -> 0 | D21: =(D12+D13)*Допущения!$E$74+D16*Допущения!$E$81+D18*Допущения!$F$59 -> 389.62 | E21: =(E12+E13)*Допущения!$E$74+E16*Допущения!$E$81+E18*Допущения!$F$59 -> 1146.09 | F21: =(F12+F13)*Допущения!$E$74+F16*Допущения!$E$81+F18*Допущения!$F$59 -> 1522.521 | G21: =(G12+G13)*Допущения!$E$74+G16*Допущения!$E$81+G18*Допущения!$F$59 -> 2215.5969 | H21: =(H12+H13)*Допущения!$E$74+H16*Допущения!$E$81+H18*Допущения!$F$59 -> 2975.6052 | I21: =(I12+I13)*Допущения!$E$74+I16*Допущения!$E$81+I18*Допущения!$F$59 -> 3720.93 | J21: =(J12+J13)*Допущения!$E$74+J16*Допущения!$E$81+J18*Допущения!$F$59 -> 4484.9597 | ... AM21: =(AM12+AM13)*Допущения!$E$74+AM16*Допущения!$E$81+AM18*Допущения!$F$59 -> 29088.795
A22: Банок: Women's Probiotic | C22: =(C12+C13)*Допущения!$F$74+C16*Допущения!$F$81+C18*Допущения!$F$60 -> 0 | D22: =(D12+D13)*Допущения!$F$74+D16*Допущения!$F$81+D18*Допущения!$F$60 -> 150.282 | E22: =(E12+E13)*Допущения!$F$74+E16*Допущения!$F$81+E18*Допущения!$F$60 -> 443.256 | F22: =(F12+F13)*Допущения!$F$74+F16*Допущения!$F$81+F18*Допущения!$F$60 -> 591.5844 | G22: =(G12+G13)*Допущения!$F$74+G16*Допущения!$F$81+G18*Допущения!$F$60 -> 862.21476 | H22: =(H12+H13)*Допущения!$F$74+H16*Допущения!$F$81+H18*Допущения!$F$60 -> 1168.8661 | I22: =(I12+I13)*Допущения!$F$74+I16*Допущения!$F$81+I18*Допущения!$F$60 -> 1468.6307 | J22: =(J12+J13)*Допущения!$F$74+J16*Допущения!$F$81+J18*Допущения!$F$60 -> 1775.8772 | ... AM22: =(AM12+AM13)*Допущения!$F$74+AM16*Допущения!$F$81+AM18*Допущения!$F$60 -> 11580.318
A23: Банок: Magnesium Glycinate | C23: =(C12+C13)*Допущения!$G$74+C16*Допущения!$G$81+C18*Допущения!$F$61 -> 0 | D23: =(D12+D13)*Допущения!$G$74+D16*Допущения!$G$81+D18*Допущения!$F$61 -> 278.3 | E23: =(E12+E13)*Допущения!$G$74+E16*Допущения!$G$81+E18*Допущения!$F$61 -> 821.6175 | F23: =(F12+F13)*Допущения!$G$74+F16*Допущения!$G$81+F18*Допущения!$F$61 -> 1098.3308 | G23: =(G12+G13)*Допущения!$G$74+G16*Допущения!$G$81+G18*Допущения!$F$61 -> 1601.6377 | H23: =(H12+H13)*Допущения!$G$74+H16*Допущения!$G$81+H18*Допущения!$F$61 -> 2155.4639 | I23: =(I12+I13)*Допущения!$G$74+I16*Допущения!$G$81+I18*Допущения!$F$61 -> 2699.5442 | J23: =(J12+J13)*Допущения!$G$74+J16*Допущения!$G$81+J18*Допущения!$F$61 -> 3257.6531 | ... AM23: =(AM12+AM13)*Допущения!$G$74+AM16*Допущения!$G$81+AM18*Допущения!$F$61 -> 21370.796
A24: Банок: Creatine | C24: =(C12+C13)*Допущения!$H$74+C16*Допущения!$H$81+C18*Допущения!$F$62 -> 0 | D24: =(D12+D13)*Допущения!$H$74+D16*Допущения!$H$81+D18*Допущения!$F$62 -> 72.358 | E24: =(E12+E13)*Допущения!$H$74+E16*Допущения!$H$81+E18*Допущения!$F$62 -> 203.60175 | F24: =(F12+F13)*Допущения!$H$74+F16*Допущения!$H$81+F18*Допущения!$F$62 -> 249.22508 | G24: =(G12+G13)*Допущения!$H$74+G16*Допущения!$H$81+G18*Допущения!$F$62 -> 352.35577 | H24: =(H12+H13)*Допущения!$H$74+H16*Допущения!$H$81+H18*Допущения!$F$62 -> 571.99439 | I24: =(I12+I13)*Допущения!$H$74+I16*Допущения!$H$81+I18*Допущения!$F$62 -> 767.85842 | J24: =(J12+J13)*Допущения!$H$74+J16*Допущения!$H$81+J18*Допущения!$F$62 -> 965.12531 | ... AM24: =(AM12+AM13)*Допущения!$H$74+AM16*Допущения!$H$81+AM18*Допущения!$F$62 -> 5082.1196
A25: Банок всего | C25: =SUM(C21:C24) -> 0 | D25: =SUM(D21:D24) -> 890.56 | E25: =SUM(E21:E24) -> 2614.5653 | F25: =SUM(F21:F24) -> 3461.6612 | G25: =SUM(G21:G24) -> 5031.8051 | H25: =SUM(H21:H24) -> 6871.9296 | I25: =SUM(I21:I24) -> 8656.9633 | J25: =SUM(J21:J24) -> 10483.615 | ... AM25: =SUM(AM21:AM24) -> 67122.028
A26: Себестоимость банки (ступень по объёму месяца)
A27: Банка: Colostrum | C27: =IFERROR(INDEX(Допущения!$H$59:$O$59,MATCH(C21,Допущения!$H$58:$O$58,1)),Допущения!$H$59)*Допущения!$E$19 -> 8.52 | D27: =IFERROR(INDEX(Допущения!$H$59:$O$59,MATCH(D21,Допущения!$H$58:$O$58,1)),Допущения!$H$59)*Допущения!$E$19 -> 8.37 | E27: =IFERROR(INDEX(Допущения!$H$59:$O$59,MATCH(E21,Допущения!$H$58:$O$58,1)),Допущения!$H$59)*Допущения!$E$19 -> 7.97 | F27: =IFERROR(INDEX(Допущения!$H$59:$O$59,MATCH(F21,Допущения!$H$58:$O$58,1)),Допущения!$H$59)*Допущения!$E$19 -> 7.97 | G27: =IFERROR(INDEX(Допущения!$H$59:$O$59,MATCH(G21,Допущения!$H$58:$O$58,1)),Допущения!$H$59)*Допущения!$E$19 -> 7.97 | H27: =IFERROR(INDEX(Допущения!$H$59:$O$59,MATCH(H21,Допущения!$H$58:$O$58,1)),Допущения!$H$59)*Допущения!$E$19 -> 7.82 | I27: =IFERROR(INDEX(Допущения!$H$59:$O$59,MATCH(I21,Допущения!$H$58:$O$58,1)),Допущения!$H$59)*Допущения!$E$19 -> 7.82 | J27: =IFERROR(INDEX(Допущения!$H$59:$O$59,MATCH(J21,Допущения!$H$58:$O$58,1)),Допущения!$H$59)*Допущения!$E$19 -> 7.82 | ... AM27: =IFERROR(INDEX(Допущения!$H$59:$O$59,MATCH(AM21,Допущения!$H$58:$O$58,1)),Допущения!$H$59)*Допущения!$E$19 -> 7.12
A28: Банка: Women's Probiotic | C28: =IFERROR(INDEX(Допущения!$H$60:$O$60,MATCH(C22,Допущения!$H$58:$O$58,1)),Допущения!$H$60)*Допущения!$E$19 -> 8.34 | D28: =IFERROR(INDEX(Допущения!$H$60:$O$60,MATCH(D22,Допущения!$H$58:$O$58,1)),Допущения!$H$60)*Допущения!$E$19 -> 8.34 | E28: =IFERROR(INDEX(Допущения!$H$60:$O$60,MATCH(E22,Допущения!$H$58:$O$58,1)),Допущения!$H$60)*Допущения!$E$19 -> 7.99 | F28: =IFERROR(INDEX(Допущения!$H$60:$O$60,MATCH(F22,Допущения!$H$58:$O$58,1)),Допущения!$H$60)*Допущения!$E$19 -> 7.64 | G28: =IFERROR(INDEX(Допущения!$H$60:$O$60,MATCH(G22,Допущения!$H$58:$O$58,1)),Допущения!$H$60)*Допущения!$E$19 -> 7.64 | H28: =IFERROR(INDEX(Допущения!$H$60:$O$60,MATCH(H22,Допущения!$H$58:$O$58,1)),Допущения!$H$60)*Допущения!$E$19 -> 7.44 | I28: =IFERROR(INDEX(Допущения!$H$60:$O$60,MATCH(I22,Допущения!$H$58:$O$58,1)),Допущения!$H$60)*Допущения!$E$19 -> 7.44 | J28: =IFERROR(INDEX(Допущения!$H$60:$O$60,MATCH(J22,Допущения!$H$58:$O$58,1)),Допущения!$H$60)*Допущения!$E$19 -> 7.44 | ... AM28: =IFERROR(INDEX(Допущения!$H$60:$O$60,MATCH(AM22,Допущения!$H$58:$O$58,1)),Допущения!$H$60)*Допущения!$E$19 -> 6.59
