Workbook

Sheet Допущения
A1: The Aldera: экономика 4 SKU капсул в саше, 29.10.2026
A2: Синие цифры можно менять, всё остальное считается само. Жёлтым отмечены самые неуверенные допущения (проверить в КП).
A3: Партия
A4: Продуктов (SKU) | B4: 4
A5: Коробок на продукт | B5: 1000
A6: Коробок всего | B6: =B4*B5 -> 4000
A7: Капсул в коробке | B7: 60
A8: Саше в коробке | B8: 30
A10: Себестоимость: сценарии | B10: Модель 28.10 (пилот, США) | C10: A. Китай, готовые саше, морем | D10: B. Китай, готовые саше, самолётом | E10: C. Капсулы из Китая самолётом + фасовка в США | F10: D. США: капсулы и фасовка (по КП FAME)
A11: Продукт: готовые саше или капсулы, $ за коробку | B11: 2.5 | C11: 1.85 | D11: 1.85 | E11: 1 | F11: 6
A12: Фасовка в саше в США, $ за саше | B12: 0.25 | C12: 0 | D12: 0 | E12: 0.12 | F12: 0.12
A13: Коробка, $ за штуку (если не входит в цену) | B13: 0.9 | C13: 0 | D13: 0 | E13: 0.45 | F13: 0.45
A14: Доставка партии до порта или склада, $ | B14: 2000 | C14: 1200 | D14: 5180 | E14: 1260 | F14: 300
A15: Пошлина, % от стоимости товара | B15: 0 | C15: 0.35 | D15: 0.35 | E15: 0.35 | F15: 0
A16: Брокер и таможенное оформление FDA, $ на партию | B16: 0 | C16: 500 | D16: 500 | E16: 500 | F16: 0
A17: Анализ партий в независимой лаборатории, $ на партию | B17: 0 | C17: 1800 | D17: 1800 | E17: 1800 | F17: 1800
A18: Импорт: программа FSVP и консультант, разово, $ | B18: 0 | C18: 2000 | D18: 2000 | E18: 2000 | F18: 0
A19: Доставка от порта до склада по США, $ на партию | B19: 0 | C19: 300 | D19: 300 | E19: 300 | F19: 0
A20: Срок до склада (справочно) | B20: 8-12 недель | C20: 2-3 нед. производство + 5-6 морем | D20: 2-3 нед. + ~1 нед. самолёт | E20: 2-3 нед. + 1 нед. + 2-3 нед. фасовка | F20: 8-12 недель (FAME 12)
A21: Законная надпись на упаковке | B21: Made in USA with imported ingredients | C21: Made in China | D21: Made in China | E21: Packed in USA with capsules made in China | F21: Made in USA with imported ingredients
A23: Цены и каналы
A24: Цена 1 коробки, $ | B24: 34
A25: Средняя скидка | B25: 0.1
A26: Набор из 2 коробок на сайте, $ | B26: 64
A27: Набор из 2 коробок в TikTok, $ | B27: 59
A28: Оплата на сайте, % | B28: 0.03
A29: Оплата на сайте, фикс $ | B29: 0.3
A30: Комиссия TikTok Shop, % | B30: 0.06
A31: Возвраты, % от цены | B31: 0.03
A32: Доставка покупателю с сайта, $ | B32: 8.3
A33: Доставка в TikTok (этикетка TikTok), $ | B33: 7.2
A34: Криейтору, 1 коробка | B34: 0.2
A35: Криейтору, набор | B35: 0.25
A37: Продажи первой партии (доля коробок)
A38: TikTok, 1 коробка | B38: 0.4
A39: TikTok, набор | B39: 0.3
A40: Сайт, 1 коробка | B40: 0.15
A41: Сайт, набор | B41: 0.15
A42: Сумма долей (должна быть 100%) | B42: =SUM(B38:B41) -> 1
A43: Образцы криейторам, коробок | B43: 100
...

Sheet Себестоимость
A1: Себестоимость одной коробки (30 саше, 60 капсул) на складе во Флориде
A3: $ за коробку | B3: Модель 28.10 (пилот, США) | C3: A. Китай, готовые саше, морем | D3: B. Китай, готовые саше, самолётом | E3: C. Капсулы из Китая самолётом + фасовка в США | F3: D. США: капсулы и фасовка (по КП FAME)
A4: Продукт | B4: =Допущения!B11 -> 2.5 | C4: =Допущения!C11 -> 1.85 | D4: =Допущения!D11 -> 1.85 | E4: =Допущения!E11 -> 1 | F4: =Допущения!F11 -> 6
A5: Фасовка в саше | B5: =Допущения!B12*Допущения!$B$8 -> 7.5 | C5: =Допущения!C12*Допущения!$B$8 -> 0 | D5: =Допущения!D12*Допущения!$B$8 -> 0 | E5: =Допущения!E12*Допущения!$B$8 -> 3.6 | F5: =Допущения!F12*Допущения!$B$8 -> 3.6
A6: Коробка | B6: =Допущения!B13 -> 0.9 | C6: =Допущения!C13 -> 0 | D6: =Допущения!D13 -> 0 | E6: =Допущения!E13 -> 0.45 | F6: =Допущения!F13 -> 0.45
A7: Доставка до склада | B7: =(Допущения!B14+Допущения!B19)/Допущения!$B$6 -> 0.5 | C7: =(Допущения!C14+Допущения!C19)/Допущения!$B$6 -> 0.375 | D7: =(Допущения!D14+Допущения!D19)/Допущения!$B$6 -> 1.37 | E7: =(Допущения!E14+Допущения!E19)/Допущения!$B$6 -> 0.39 | F7: =(Допущения!F14+Допущения!F19)/Допущения!$B$6 -> 0.075
A8: Пошлина | B8: =Допущения!B11*Допущения!B15 -> 0 | C8: =Допущения!C11*Допущения!C15 -> 0.6475 | D8: =Допущения!D11*Допущения!D15 -> 0.6475 | E8: =Допущения!E11*Допущения!E15 -> 0.35 | F8: =Допущения!F11*Допущения!F15 -> 0
A9: Брокер и таможня | B9: =Допущения!B16/Допущения!$B$6 -> 0 | C9: =Допущения!C16/Допущения!$B$6 -> 0.125 | D9: =Допущения!D16/Допущения!$B$6 -> 0.125 | E9: =Допущения!E16/Допущения!$B$6 -> 0.125 | F9: =Допущения!F16/Допущения!$B$6 -> 0
A10: Анализ партий | B10: =Допущения!B17/Допущения!$B$6 -> 0 | C10: =Допущения!C17/Допущения!$B$6 -> 0.45 | D10: =Допущения!D17/Допущения!$B$6 -> 0.45 | E10: =Допущения!E17/Допущения!$B$6 -> 0.45 | F10: =Допущения!F17/Допущения!$B$6 -> 0.45
A11: FSVP, разово | B11: =Допущения!B18/Допущения!$B$6 -> 0 | C11: =Допущения!C18/Допущения!$B$6 -> 0.5 | D11: =Допущения!D18/Допущения!$B$6 -> 0.5 | E11: =Допущения!E18/Допущения!$B$6 -> 0.5 | F11: =Допущения!F18/Допущения!$B$6 -> 0
A12: Итого за коробку | B12: =SUM(B4:B11) -> 11.4 | C12: =SUM(C4:C11) -> 3.9475 | D12: =SUM(D4:D11) -> 4.9425 | E12: =SUM(E4:E11) -> 6.865 | F12: =SUM(F4:F11) -> 10.575
A13: Дешевле модели 28.10 на, $ | B13: =$B$12-B12 -> 0 | C13: =$B$12-C12 -> 7.4525 | D13: =$B$12-D12 -> 6.4575 | E13: =$B$12-E12 -> 4.535 | F13: =$B$12-F12 -> 0.825
A15: Деньги на всю партию (4 SKU), $ | B15: =B12*Допущения!$B$6 -> 45600 | C15: =C12*Допущения!$B$6 -> 15790 | D15: =D12*Допущения!$B$6 -> 19770 | E15: =E12*Допущения!$B$6 -> 27460 | F15: =F12*Допущения!$B$6 -> 42300
A16: Надпись на упаковке | B16: =Допущения!B21 -> Made in USA with imported ingredients | C16: =Допущения!C21 -> Made in China | D16: =Допущения!D21 -> Made in China | E16: =Допущения!E21 -> Packed in USA with capsules made in China | F16: =Допущения!F21 -> Made in USA with imported ingredients

Sheet Прибыль
A1: Прибыль с заказа после всех расходов и первая партия
A3: Прибыль с заказа, $ | B3: Модель 28.10 (пилот, США) | C3: A. Китай, готовые саше, морем | D3: B. Китай, готовые саше, самолётом | E3: C. Капсулы из Китая самолётом + фасовка в США | F3: D. США: капсулы и фасовка (по КП FAME)
A4: Сайт, 1 коробка | B4: =Допущения!$B$24*(1-Допущения!$B$25)*(1-Допущения!$B$28-Допущения!$B$31)-Допущения!$B$29-Допущения!$B$32-Себестоимость!B12 -> 8.764 | C4: =Допущения!$B$24*(1-Допущения!$B$25)*(1-Допущения!$B$28-Допущения!$B$31)-Допущения!$B$29-Допущения!$B$32-Себестоимость!C12 -> 16.2165 | D4: =Допущения!$B$24*(1-Допущения!$B$25)*(1-Допущения!$B$28-Допущения!$B$31)-Допущения!$B$29-Допущения!$B$32-Себестоимость!D12 -> 15.2215 | E4: =Допущения!$B$24*(1-Допущения!$B$25)*(1-Допущения!$B$28-Допущения!$B$31)-Допущения!$B$29-Допущения!$B$32-Себестоимость!E12 -> 13.299 | F4: =Допущения!$B$24*(1-Допущения!$B$25)*(1-Допущения!$B$28-Допущения!$B$31)-Допущения!$B$29-Допущения!$B$32-Себестоимость!F12 -> 9.589
A5: TikTok, 1 коробка | B5: =Допущения!$B$24*(1-Допущения!$B$25)*(1-Допущения!$B$30-Допущения!$B$34-Допущения!$B$31)-Допущения!$B$33-Себестоимость!B12 -> 3.126 | C5: =Допущения!$B$24*(1-Допущения!$B$25)*(1-Допущения!$B$30-Допущения!$B$34-Допущения!$B$31)-Допущения!$B$33-Себестоимость!C12 -> 10.5785 | D5: =Допущения!$B$24*(1-Допущения!$B$25)*(1-Допущения!$B$30-Допущения!$B$34-Допущения!$B$31)-Допущения!$B$33-Себестоимость!D12 -> 9.5835 | E5: =Допущения!$B$24*(1-Допущения!$B$25)*(1-Допущения!$B$30-Допущения!$B$34-Допущения!$B$31)-Допущения!$B$33-Себестоимость!E12 -> 7.661 | F5: =Допущения!$B$24*(1-Допущения!$B$25)*(1-Допущения!$B$30-Допущения!$B$34-Допущения!$B$31)-Допущения!$B$33-Себестоимость!F12 -> 3.951
A6: Сайт, набор из 2 | B6: =Допущения!$B$26*(1-Допущения!$B$28-Допущения!$B$31)-Допущения!$B$29-Допущения!$B$32-2*Себестоимость!B12 -> 28.76 | C6: =Допущения!$B$26*(1-Допущения!$B$28-Допущения!$B$31)-Допущения!$B$29-Допущения!$B$32-2*Себестоимость!C12 -> 43.665 | D6: =Допущения!$B$26*(1-Допущения!$B$28-Допущения!$B$31)-Допущения!$B$29-Допущения!$B$32-2*Себестоимость!D12 -> 41.675 | E6: =Допущения!$B$26*(1-Допущения!$B$28-Допущения!$B$31)-Допущения!$B$29-Допущения!$B$32-2*Себестоимость!E12 -> 37.83 | F6: =Допущения!$B$26*(1-Допущения!$B$28-Допущения!$B$31)-Допущения!$B$29-Допущения!$B$32-2*Себестоимость!F12 -> 30.41
A7: TikTok, набор из 2 | B7: =Допущения!$B$27*(1-Допущения!$B$30-Допущения!$B$35-Допущения!$B$31)-Допущения!$B$33-2*Себестоимость!B12 -> 8.94 | C7: =Допущения!$B$27*(1-Допущения!$B$30-Допущения!$B$35-Допущения!$B$31)-Допущения!$B$33-2*Себестоимость!C12 -> 23.845 | D7: =Допущения!$B$27*(1-Допущения!$B$30-Допущения!$B$35-Допущения!$B$31)-Допущения!$B$33-2*Себестоимость!D12 -> 21.855 | E7: =Допущения!$B$27*(1-Допущения!$B$30-Допущения!$B$35-Допущения!$B$31)-Допущения!$B$33-2*Себестоимость!E12 -> 18.01 | F7: =Допущения!$B$27*(1-Допущения!$B$30-Допущения!$B$35-Допущения!$B$31)-Допущения!$B$33-2*Себестоимость!F12 -> 10.59
A8: Маржа TikTok, 1 коробка, % от цены | B8: =IFERROR(B5/(Допущения!$B$24*(1-Допущения!$B$25)),0) -> 0.10215686 | C8: =IFERROR(C5/(Допущения!$B$24*(1-Допущения!$B$25)),0) -> 0.34570261 | D8: =IFERROR(D5/(Допущения!$B$24*(1-Допущения!$B$25)),0) -> 0.31318627 | E8: =IFERROR(E5/(Допущения!$B$24*(1-Допущения!$B$25)),0) -> 0.25035948 | F8: =IFERROR(F5/(Допущения!$B$24*(1-Допущения!$B$25)),0) -> 0.12911765
A10: Первая партия: 4 SKU | B10: Модель 28.10 (пилот, США) | C10: A. Китай, готовые саше, морем | D10: B. Китай, готовые саше, самолётом | E10: C. Капсулы из Китая самолётом + фасовка в США | F10: D. США: капсулы и фасовка (по КП FAME)
A11: Прибыль на коробку в среднем по каналам, $ | B11: =Допущения!$B$38*B5+Допущения!$B$39*B7/2+Допущения!$B$40*B4+Допущения!$B$41*B6/2 -> 6.063 | C11: =Допущения!$B$38*C5+Допущения!$B$39*C7/2+Допущения!$B$40*C4+Допущения!$B$41*C6/2 -> 13.5155 | D11: =Допущения!$B$38*D5+Допущения!$B$39*D7/2+Допущения!$B$40*D4+Допущения!$B$41*D6/2 -> 12.5205 | E11: =Допущения!$B$38*E5+Допущения!$B$39*E7/2+Допущения!$B$40*E4+Допущения!$B$41*E6/2 -> 10.598 | F11: =Допущения!$B$38*F5+Допущения!$B$39*F7/2+Допущения!$B$40*F4+Допущения!$B$41*F6/2 -> 6.888
A12: Коробок на продажу (без образцов) | B12: =Допущения!$B$6-Допущения!$B$43 -> 3900 | C12: =Допущения!$B$6-Допущения!$B$43 -> 3900 | D12: =Допущения!$B$6-Допущения!$B$43 -> 3900 | E12: =Допущения!$B$6-Допущения!$B$43 -> 3900 | F12: =Допущения!$B$6-Допущения!$B$43 -> 3900
A13: Прибыль с продаж партии, $ | B13: =B11*B12 -> 23645.7 | C13: =C11*C12 -> 52710.45 | D13: =D11*D12 -> 48829.95 | E13: =E11*E12 -> 41332.2 | F13: =F11*F12 -> 26863.2
A14: Образцы криейторам (товар и доставка), $ | B14: =-Допущения!$B$43*(Себестоимость!B12+Допущения!$B$44) -> -1970 | C14: =-Допущения!$B$43*(Себестоимость!C12+Допущения!$B$44) -> -1224.75 | D14: =-Допущения!$B$43*(Себестоимость!D12+Допущения!$B$44) -> -1324.25 | E14: =-Допущения!$B$43*(Себестоимость!E12+Допущения!$B$44) -> -1516.5 | F14: =-Допущения!$B$43*(Себестоимость!F12+Допущения!$B$44) -> -1887.5
A15: Чистая прибыль партии, $ | B15: =B13+B14 -> 21675.7 | C15: =C13+C14 -> 51485.7 | D15: =D13+D14 -> 47505.7 | E15: =E13+E14 -> 39815.7 | F15: =F13+F14 -> 24975.7
A16: Вложено в партию, $ | B16: =Себестоимость!B15 -> 45600 | C16: =Себестоимость!C15 -> 15790 | D16: =Себестоимость!D15 -> 19770 | E16: =Себестоимость!E15 -> 27460 | F16: =Себестоимость!F15 -> 42300
A17: Отдача на вложенные деньги | B17: =IFERROR(B15/B16,0) -> 0.4753443 | C17: =IFERROR(C15/C16,0) -> 3.2606523 | D17: =IFERROR(D15/D16,0) -> 2.4029186 | E17: =IFERROR(E15/E16,0) -> 1.4499527 | F17: =IFERROR(F15/F16,0) -> 0.59044208
A18: Коробок продать, чтобы вернуть вложенное | B18: =IFERROR(B16/(B11+Себестоимость!B12),0) -> 2611.2352 | C18: =IFERROR(C16/(C11+Себестоимость!C12),0) -> 904.19745 | D18: =IFERROR(D16/(D11+Себестоимость!D12),0) -> 1132.1079 | E18: =IFERROR(E16/(E11+Себестоимость!E12),0) -> 1572.4675 | F18: =IFERROR(F16/(F11+Себестоимость!F12),0) -> 2422.2642
A20: Расчёт без налогов, рекламы Spark Ads, дизайна, склада и подписок. Прибыль с заказа совпадает с моделью 28.10 в колонке B (проверка формул).
